Workbook
Name REGIONES: Listas_Validacion!$A$3:$A$12
Name ESTADOS: Listas_Validacion!$C$3:$C$8
Name CAUSALES: Listas_Validacion!$E$3:$E$9
Name ESTATUS_ACTA: Listas_Validacion!$G$3:$G$4

Sheet Guia_Diligenciamiento
A1: GUÍA DE DILIGENCIAMIENTO — BITÁCORA DIARIA DE MANTENIMIENTOS Y AUDITORÍA DE CALIDAD
A2: Esta bitácora es el INSUMO del tablero de control (dashboard). El plan maestro (825 registros) viene del cronograma preventivo; la alimenta el equipo de calidad (PMU COLSOF) con el estado real de cada mantenimiento. Las columnas grises (N-Q, W y X) se calculan solas: NO se editan.
A4: 0 · CÓMO SE AUTOREGISTRA LA SEDE (SBAN)
A5: En la columna A escriba el SBAN de la oficina (el identificador único del cronograma). Nombre_Oficina, Municipio, Departamento, Región y Horario se llenan SOLOS desde la pestaña Cronograma_Maestro. Si queda vacío, el SBAN no existe en el cronograma: revíselo.
A7: 0B · FECHAS SIN ERRORES
A8: Fechas en DÍA/MES/AÑO: 05/04/2026 = 5 de ABRIL. Las celdas muestran dd/mm/aaaa y RECHAZAN fechas inválidas, fuera de rango (2026-2031) o valores que queden como texto. Prefiera el CALENDARIO nativo (icono al seleccionar la celda).
A9: Cada fila tiene un CHEQUEO automático (columna W): OK = coherentes; REVISAR = hay una inconsistencia (fin < inicio, cierre < inicio real, cierre admin < cierre operativo). Corrija antes de cerrar.
A11: 1 · FLUJO DEL MANTENIMIENTO
A12: Programada → En Proceso → Finalizada → Sede_Cerrada (cerrada por calidad)
A13: Desvíos: Programada → Reprogramada (con nueva fecha y causal) | Cualquier estado → Cancelada
A15: 2 · ¿QUÉ DILIGENCIAR EN CADA MOMENTO?
A16: Momento | B16: Columnas | C16: Qué hacer
A17: Al programar | B17: A (SBAN), L | C17: Escribir el SBAN (el resto se autocompleta) y Estado = Programada
A18: Al llegar a la sede | B18: J | C18: Fecha_Inicio_Real y Estado = En Proceso
A19: Al terminar en campo | B19: K, L, R, V | C19: Fecha_Cierre_Operativo, Estado = Finalizada, causal si se desvió, observaciones
A20: Al reprogramar | B20: M, L, R | C20: Nueva fecha (M), Estado = Reprogramada y causal
A21: Al cerrar por calidad | B21: S, T, L, U | C21: Acta Firmada, fecha de firma, Estado = Sede_Cerrada, cantidad de equipos
A23: 3 · DECISIÓN POR ESTADO
A24: Estado | B24: Exige | C24: Permite cerrar con
A25: Finalizada | B25: Fecha_Cierre_Operativo (K) | C25: No: falta firma de calidad
A26: Sede_Cerrada | B26: Acta FIRMADA (S) + fecha de firma (T) | C26: Sí: ejecutada y cerrada
A27: Reprogramada | B27: Nueva fecha (M) + causal (R) | C27: No: pasa a pendiente con nueva fecha
A28: Cancelada | B28: — | C28: No: no cuenta en cumplimiento
A30: 4 · CAMPOS POR GRUPO (MOUSE SOBRE LOS ENCABEZADOS = NOTA)
A31: Grupo | B31: Columnas | C31: Contenido
A32: 1 · Identificación (azul oscuro) | B32: A-E | C32: SBAN (clave) + oficina/municipio/depto/región autocompletados
A33: 2 · Programación (azul) | B33: F-I | C33: Técnicos (calidad = PMU COLSOF) y fechas programadas
A34: 3 · Ejecución (verde azulado) | B34: J-M | C34: Fechas reales y estado
A35: 4 · Cálculo automático (gris) | B35: N-Q | C35: Cumplimiento y desviación: NO EDITAR
A36: 5 · Calidad, cierre y horario (verde) | B36: R-X | C36: Causal, acta, cierre, equipos, observaciones, chequeo y horario
A38: 5 · REGLAS IMPORTANTES
A39: • El SBAN es la llave única: si no está en el cronograma, la fila no se autocompleta (revíselo).
A40: • Fechas SIEMPRE en DÍA/MES/AÑO; use el calendario. La celda rechaza inválidas o texto.
A41: • El acta tiene 2 opciones: Pendiente Firma o Firmada. Para cerrar, debe quedar FIRMADA.
A42: • Causal: Repuesto Faltante · Director Oficina No Disponible · Clima · Falla Técnica · Reprogramación Cliente · Logística/Acceso. Si cumplió: N/A - A Tiempo.
A43: • Si Estado = Reprogramada, el Excel EXIGE Fecha_Nueva_Programada.
A44: • Calidad es PMU COLSOF (columna G fija). Columnas grises N-Q, W y X: no editar.
A45: • Si necesita más filas: copie una fila en blanco y péguela debajo (mantiene fórmulas y listas).
A47: 6 · ¿CÓMO SE ACTUALIZA EL DASHBOARD?
A48: 1) Guarde este archivo. 2) Súbalo al repositorio (commit + push o arrastre en GitHub). 3) GitHub Actions regenera los datos (o diario a las 06:00 CO) y Vercel publica en ~2 min. El tablero NUNCA se apaga.
...

Sheet Bitacora_Diaria
A1: SBAN | B1: Nombre_Oficina | C1: Municipio | D1: Departamento | E1: Region | F1: Tecnico_Operativo | G1: Tecnico_Calidad | H1: Fecha_Programada_Inicio | I1: Fecha_Programada_Fin | J1: Fecha_Inicio_Real | K1: Fecha_Cierre_Operativo | L1: Estado_Mantenimiento | M1: Fecha_Nueva_Programada | N1: Cumpli_Ingreso | O1: Cumpli_Salida | P1: Cumpli_Cronograma | Q1: Dias_Desviacion | R1: Causal_Desviacion | S1: Estatus_Acta | T1: Fecha_Cierre_Administrativo | U1: Cantidad_Equipos | V1: Observaciones_Calidad | W1: Chequeo_Fechas | X1: Horario_Atencion
A2: 10 | B2: =SI([@SBAN]="";"";BUSCARV([@SBAN];Cronograma_Maestro!$A:$M;2;FALSO)) | C2: =SI([@SBAN]="";"";BUSCARV([@SBAN];Cronograma_Maestro!$A:$M;3;FALSO)) | D2: =SI([@SBAN]="";"";BUSCARV([@SBAN];Cronograma_Maestro!$A:$M;4;FALSO)) | E2: =SI([@SBAN]="";"";BUSCARV([@SBAN];Cronograma_Maestro!$A:$M;5;FALSO)) | F2: Anderson Forero Mora | G2: PMU COLSOF | H2: 46302 | I2: 46304 | L2: Programada | N2: =SI(O([@[Fecha_Programada_Inicio]]="";[@[Fecha_Inicio_Real]]="");"";SI([@[Fecha_Inicio_Real]]<=[@[Fecha_Programada_Inicio]];"SÍ";"NO")) | O2: =SI(O([@[Fecha_Programada_Fin]]="";[@[Fecha_Cierre_Operativo]]="");"";SI([@[Fecha_Cierre_Operativo]]<=SI([@[Fecha_Nueva_Programada]]<>"";[@[Fecha_Nueva_Programada]];[@[Fecha_Programada_Fin]]);"SÍ";"NO")) | P2: =SI(O([@[Cumpli_Ingreso]]="";[@[Cumpli_Salida]]="");"";SI(Y([@[Cumpli_Ingreso]]="SÍ";[@[Cumpli_Salida]]="SÍ");"SÍ";"NO")) | Q2: =SI(O([@[Fecha_Programada_Fin]]="";[@[Fecha_Cierre_Operativo]]="");"";MAX(0;ENTERO([@[Fecha_Cierre_Operativo]])-ENTERO(SI([@[Fecha_Nueva_Programada]]<>"";[@[Fecha_Nueva_Programada]];[@[Fecha_Programada_Fin]]))) | U2: 56 | W2: =SI.ERROR(SI(O([@[Fecha_Programada_Inicio]]="";[@[Fecha_Programada_Fin]]="");"";SI(Y([@[Fecha_Programada_Fin]]>=[@[Fecha_Programada_Inicio]];SI([@[Fecha_Cierre_Operativo]]="";VERDADERO;[@[Fecha_Cierre_Operativo]]>=[@[Fecha_Inicio_Real]]);SI([@[Fecha_Cierre_Administrativo]]="";VERDADERO;Y([@[Fecha_Cierre_Operativo]]<>"";[@[Fecha_Cierre_Administrativo]]>=[@[Fecha_Cierre_Operativo]])));"OK";"REVISAR"));"REVISAR") | X2: =SI([@SBAN]="";"";BUSCARV([@SBAN];Cronograma_Maestro!$A:$M;6;FALSO))
A3: 20 | B3: =SI([@SBAN]="";"";BUSCARV([@SBAN];Cronograma_Maestro!$A:$M;2;FALSO)) | C3: =SI([@SBAN]="";"";BUSCARV([@SBAN];Cronograma_Maestro!$A:$M;3;FALSO)) | D3: =SI([@SBAN]="";"";BUSCARV([@SBAN];Cronograma_Maestro!$A:$M;4;FALSO)) | E3: =SI([@SBAN]="";"";BUSCARV([@SBAN];Cronograma_Maestro!$A:$M;5;FALSO)) | F3: Anderson Forero Mora | G3: PMU COLSOF | H3: 46300 | I3: 46301 | L3: Programada | N3: =SI(O([@[Fecha_Programada_Inicio]]="";[@[Fecha_Inicio_Real]]="");"";SI([@[Fecha_Inicio_Real]]<=[@[Fecha_Programada_Inicio]];"SÍ";"NO")) | O3: =SI(O([@[Fecha_Programada_Fin]]="";[@[Fecha_Cierre_Operativo]]="");"";SI([@[Fecha_Cierre_Operativo]]<=SI([@[Fecha_Nueva_Programada]]<>"";[@[Fecha_Nueva_Programada]];[@[Fecha_Programada_Fin]]);"SÍ";"NO")) | P3: =SI(O([@[Cumpli_Ingreso]]="";[@[Cumpli_Salida]]="");"";SI(Y([@[Cumpli_Ingreso]]="SÍ";[@[Cumpli_Salida]]="SÍ");"SÍ";"NO")) | Q3: =SI(O([@[Fecha_Programada_Fin]]="";[@[Fecha_Cierre_Operativo]]="");"";MAX(0;ENTERO([@[Fecha_Cierre_Operativo]])-ENTERO(SI([@[Fecha_Nueva_Programada]]<>"";[@[Fecha_Nueva_Programada]];[@[Fecha_Programada_Fin]]))) | U3: 28 | W3: =SI.ERROR(SI(O([@[Fecha_Programada_Inicio]]="";[@[Fecha_Programada_Fin]]="");"";SI(Y([@[Fecha_Programada_Fin]]>=[@[Fecha_Programada_Inicio]];SI([@[Fecha_Cierre_Operativo]]="";VERDADERO;[@[Fecha_Cierre_Operativo]]>=[@[Fecha_Inicio_Real]]);SI([@[Fecha_Cierre_Administrativo]]="";VERDADERO;Y([@[Fecha_Cierre_Operativo]]<>"";[@[Fecha_Cierre_Administrativo]]>=[@[Fecha_Cierre_Operativo]])));"OK";"REVISAR"));"REVISAR") | X3: =SI([@SBAN]="";"";BUSCARV([@SBAN];Cronograma_Maestro!$A:$M;6;FALSO))
A4: 70 | B4: =SI([@SBAN]="";"";BUSCARV([@SBAN];Cronograma_Maestro!$A:$M;2;FALSO)) | C4: =SI([@SBAN]="";"";BUSCARV([@SBAN];Cronograma_Maestro!$A:$M;3;FALSO)) | D4: =SI([@SBAN]="";"";BUSCARV([@SBAN];Cronograma_Maestro!$A:$M;4;FALSO)) | E4: =SI([@SBAN]="";"";BUSCARV([@SBAN];Cronograma_Maestro!$A:$M;5;FALSO)) | F4: Anderson Forero Mora | G4: PMU COLSOF | H4: 46293 | I4: 46295 | L4: Programada | N4: =SI(O([@[Fecha_Programada_Inicio]]="";[@[Fecha_Inicio_Real]]="");"";SI([@[Fecha_Inicio_Real]]<=[@[Fecha_Programada_Inicio]];"SÍ";"NO")) | O4: =SI(O([@[Fecha_Programada_Fin]]="";[@[Fecha_Cierre_Operativo]]="");"";SI([@[Fecha_Cierre_Operativo]]<=SI([@[Fecha_Nueva_Programada]]<>"";[@[Fecha_Nueva_Programada]];[@[Fecha_Programada_Fin]]);"SÍ";"NO")) | P4: =SI(O([@[Cumpli_Ingreso]]="";[@[Cumpli_Salida]]="");"";SI(Y([@[Cumpli_Ingreso]]="SÍ";[@[Cumpli_Salida]]="SÍ");"SÍ";"NO")) | Q4: =SI(O([@[Fecha_Programada_Fin]]="";[@[Fecha_Cierre_Operativo]]="");"";MAX(0;ENTERO([@[Fecha_Cierre_Operativo]])-ENTERO(SI([@[Fecha_Nueva_Programada]]<>"";[@[Fecha_Nueva_Programada]];[@[Fecha_Programada_Fin]]))) | U4: 45 | W4: =SI.ERROR(SI(O([@[Fecha_Programada_Inicio]]="";[@[Fecha_Programada_Fin]]="");"";SI(Y([@[Fecha_Programada_Fin]]>=[@[Fecha_Programada_Inicio]];SI([@[Fecha_Cierre_Operativo]]="";VERDADERO;[@[Fecha_Cierre_Operativo]]>=[@[Fecha_Inicio_Real]]);SI([@[Fecha_Cierre_Administrativo]]="";VERDADERO;Y([@[Fecha_Cierre_Operativo]]<>"";[@[Fecha_Cierre_Administrativo]]>=[@[Fecha_Cierre_Operativo]])));"OK";"REVISAR"));"REVISAR") | X4: =SI([@SBAN]="";"";BUSCARV([@SBAN];Cronograma_Maestro!$A:$M;6;FALSO))
A5: 230 | B5: =SI([@SBAN]="";"";BUSCARV([@SBAN];Cronograma_Maestro!$A:$M;2;FALSO)) | C5: =SI([@SBAN]="";"";BUSCARV([@SBAN];Cronograma_Maestro!$A:$M;3;FALSO)) | D5: =SI([@SBAN]="";"";BUSCARV([@SBAN];Cronograma_Maestro!$A:$M;4;FALSO)) | E5: =SI([@SBAN]="";"";BUSCARV([@SBAN];Cronograma_Maestro!$A:$M;5;FALSO)) | F5: Anderson Forero Mora | G5: PMU COLSOF | H5: 46321 | I5: 46321 | L5: Programada | N5: =SI(O([@[Fecha_Programada_Inicio]]="";[@[Fecha_Inicio_Real]]="");"";SI([@[Fecha_Inicio_Real]]<=[@[Fecha_Programada_Inicio]];"SÍ";"NO")) | O5: =SI(O([@[Fecha_Programada_Fin]]="";[@[Fecha_Cierre_Operativo]]="");"";SI([@[Fecha_Cierre_Operativo]]<=SI([@[Fecha_Nueva_Programada]]<>"";[@[Fecha_Nueva_Programada]];[@[Fecha_Programada_Fin]]);"SÍ";"NO")) | P5: =SI(O([@[Cumpli_Ingreso]]="";[@[Cumpli_Salida]]="");"";SI(Y([@[Cumpli_Ingreso]]="SÍ";[@[Cumpli_Salida]]="SÍ");"SÍ";"NO")) | Q5: =SI(O([@[Fecha_Programada_Fin]]="";[@[Fecha_Cierre_Operativo]]="");"";MAX(0;ENTERO([@[Fecha_Cierre_Operativo]])-ENTERO(SI([@[Fecha_Nueva_Programada]]<>"";[@[Fecha_Nueva_Programada]];[@[Fecha_Programada_Fin]]))) | U5: 25 | W5: =SI.ERROR(SI(O([@[Fecha_Programada_Inicio]]="";[@[Fecha_Programada_Fin]]="");"";SI(Y([@[Fecha_Programada_Fin]]>=[@[Fecha_Programada_Inicio]];SI([@[Fecha_Cierre_Operativo]]="";VERDADERO;[@[Fecha_Cierre_Operativo]]>=[@[Fecha_Inicio_Real]]);SI([@[Fecha_Cierre_Administrativo]]="";VERDADERO;Y([@[Fecha_Cierre_Operativo]]<>"";[@[Fecha_Cierre_Administrativo]]>=[@[Fecha_Cierre_Operativo]])));"OK";"REVISAR"));"REVISAR") | X5: =SI([@SBAN]="";"";BUSCARV([@SBAN];Cronograma_Maestro!$A:$M;6;FALSO))
A6: 250 | B6: =SI([@SBAN]="";"";BUSCARV([@SBAN];Cronograma_Maestro!$A:$M;2;FALSO)) | C6: =SI([@SBAN]="";"";BUSCARV([@SBAN];Cronograma_Maestro!$A:$M;3;FALSO)) | D6: =SI([@SBAN]="";"";BUSCARV([@SBAN];Cronograma_Maestro!$A:$M;4;FALSO)) | E6: =SI([@SBAN]="";"";BUSCARV([@SBAN];Cronograma_Maestro!$A:$M;5;FALSO)) | F6: Anderson Forero Mora | G6: PMU COLSOF | H6: 46316 | I6: 46316 | L6: Programada | N6: =SI(O([@[Fecha_Programada_Inicio]]="";[@[Fecha_Inicio_Real]]="");"";SI([@[Fecha_Inicio_Real]]<=[@[Fecha_Programada_Inicio]];"SÍ";"NO")) | O6: =SI(O([@[Fecha_Programada_Fin]]="";[@[Fecha_Cierre_Operativo]]="");"";SI([@[Fecha_Cierre_Operativo]]<=SI([@[Fecha_Nueva_Programada]]<>"";[@[Fecha_Nueva_Programada]];[@[Fecha_Programada_Fin]]);"SÍ";"NO")) | P6: =SI(O([@[Cumpli_Ingreso]]="";[@[Cumpli_Salida]]="");"";SI(Y([@[Cumpli_Ingreso]]="SÍ";[@[Cumpli_Salida]]="SÍ");"SÍ";"NO")) | Q6: =SI(O([@[Fecha_Programada_Fin]]="";[@[Fecha_Cierre_Operativo]]="");"";MAX(0;ENTERO([@[Fecha_Cierre_Operativo]])-ENTERO(SI([@[Fecha_Nueva_Programada]]<>"";[@[Fecha_Nueva_Programada]];[@[Fecha_Programada_Fin]]))) | U6: 19 | W6: =SI.ERROR(SI(O([@[Fecha_Programada_Inicio]]="";[@[Fecha_Programada_Fin]]="");"";SI(Y([@[Fecha_Programada_Fin]]>=[@[Fecha_Programada_Inicio]];SI([@[Fecha_Cierre_Operativo]]="";VERDADERO;[@[Fecha_Cierre_Operativo]]>=[@[Fecha_Inicio_Real]]);SI([@[Fecha_Cierre_Administrativo]]="";VERDADERO;Y([@[Fecha_Cierre_Operativo]]<>"";[@[Fecha_Cierre_Administrativo]]>=[@[Fecha_Cierre_Operativo]])));"OK";"REVISAR"));"REVISAR") | X6: =SI([@SBAN]="";"";BUSCARV([@SBAN];Cronograma_Maestro!$A:$M;6;FALSO))
A7: 260 | B7: =SI([@SBAN]="";"";BUSCARV([@SBAN];Cronograma_Maestro!$A:$M;2;FALSO)) | C7: =SI([@SBAN]="";"";BUSCARV([@SBAN];Cronograma_Maestro!$A:$M;3;FALSO)) | D7: =SI([@SBAN]="";"";BUSCARV([@SBAN];Cronograma_Maestro!$A:$M;4;FALSO)) | E7: =SI([@SBAN]="";"";BUSCARV([@SBAN];Cronograma_Maestro!$A:$M;5;FALSO)) | F7: Anderson Forero Mora | G7: PMU COLSOF | H7: 46308 | I7: 46309 | L7: Programada | N7: =SI(O([@[Fecha_Programada_Inicio]]="";[@[Fecha_Inicio_Real]]="");"";SI([@[Fecha_Inicio_Real]]<=[@[Fecha_Programada_Inicio]];"SÍ";"NO")) | O7: =SI(O([@[Fecha_Programada_Fin]]="";[@[Fecha_Cierre_Operativo]]="");"";SI([@[Fecha_Cierre_Operativo]]<=SI([@[Fecha_Nueva_Programada]]<>"";[@[Fecha_Nueva_Programada]];[@[Fecha_Programada_Fin]]);"SÍ";"NO")) | P7: =SI(O([@[Cumpli_Ingreso]]="";[@[Cumpli_Salida]]="");"";SI(Y([@[Cumpli_Ingreso]]="SÍ";[@[Cumpli_Salida]]="SÍ");"SÍ";"NO")) | Q7: =SI(O([@[Fecha_Programada_Fin]]="";[@[Fecha_Cierre_Operativo]]="");"";MAX(0;ENTERO([@[Fecha_Cierre_Operativo]])-ENTERO(SI([@[Fecha_Nueva_Programada]]<>"";[@[Fecha_Nueva_Programada]];[@[Fecha_Programada_Fin]]))) | U7: 37 | W7: =SI.ERROR(SI(O([@[Fecha_Programada_Inicio]]="";[@[Fecha_Programada_Fin]]="");"";SI(Y([@[Fecha_Programada_Fin]]>=[@[Fecha_Programada_Inicio]];SI([@[Fecha_Cierre_Operativo]]="";VERDADERO;[@[Fecha_Cierre_Operativo]]>=[@[Fecha_Inicio_Real]]);SI([@[Fecha_Cierre_Administrativo]]="";VERDADERO;Y([@[Fecha_Cierre_Operativo]]<>"";[@[Fecha_Cierre_Administrativo]]>=[@[Fecha_Cierre_Operativo]])));"OK";"REVISAR"));"REVISAR") | X7: =SI([@SBAN]="";"";BUSCARV([@SBAN];Cronograma_Maestro!$A:$M;6;FALSO))
A8: 280 | B8: =SI([@SBAN]="";"";BUSCARV([@SBAN];Cronograma_Maestro!$A:$M;2;FALSO)) | C8: =SI([@SBAN]="";"";BUSCARV([@SBAN];Cronograma_Maestro!$A:$M;3;FALSO)) | D8: =SI([@SBAN]="";"";BUSCARV([@SBAN];Cronograma_Maestro!$A:$M;4;FALSO)) | E8: =SI([@SBAN]="";"";BUSCARV([@SBAN];Cronograma_Maestro!$A:$M;5;FALSO)) | F8: Anderson Forero Mora | G8: PMU COLSOF | H8: 46297 | I8: 46297 | L8: Programada | N8: =SI(O([@[Fecha_Programada_Inicio]]="";[@[Fecha_Inicio_Real]]="");"";SI([@[Fecha_Inicio_Real]]<=[@[Fecha_Programada_Inicio]];"SÍ";"NO")) | O8: =SI(O([@[Fecha_Programada_Fin]]="";[@[Fecha_Cierre_Operativo]]="");"";SI([@[Fecha_Cierre_Operativo]]<=SI([@[Fecha_Nueva_Programada]]<>"";[@[Fecha_Nueva_Programada]];[@[Fecha_Programada_Fin]]);"SÍ";"NO")) | P8: =SI(O([@[Cumpli_Ingreso]]="";[@[Cumpli_Salida]]="");"";SI(Y([@[Cumpli_Ingreso]]="SÍ";[@[Cumpli_Salida]]="SÍ");"SÍ";"NO")) | Q8: =SI(O([@[Fecha_Programada_Fin]]="";[@[Fecha_Cierre_Operativo]]="");"";MAX(0;ENTERO([@[Fecha_Cierre_Operativo]])-ENTERO(SI([@[Fecha_Nueva_Programada]]<>"";[@[Fecha_Nueva_Programada]];[@[Fecha_Programada_Fin]]))) | U8: 16 | W8: =SI.ERROR(SI(O([@[Fecha_Programada_Inicio]]="";[@[Fecha_Programada_Fin]]="");"";SI(Y([@[Fecha_Programada_Fin]]>=[@[Fecha_Programada_Inicio]];SI([@[Fecha_Cierre_Operativo]]="";VERDADERO;[@[Fecha_Cierre_Operativo]]>=[@[Fecha_Inicio_Real]]);SI([@[Fecha_Cierre_Administrativo]]="";VERDADERO;Y([@[Fecha_Cierre_Operativo]]<>"";[@[Fecha_Cierre_Administrativo]]>=[@[Fecha_Cierre_Operativo]])));"OK";"REVISAR"));"REVISAR") | X8: =SI([@SBAN]="";"";BUSCARV([@SBAN];Cronograma_Maestro!$A:$M;6;FALSO))
A9: 290 | B9: =SI([@SBAN]="";"";BUSCARV([@SBAN];Cronograma_Maestro!$A:$M;2;FALSO)) | C9: =SI([@SBAN]="";"";BUSCARV([@SBAN];Cronograma_Maestro!$A:$M;3;FALSO)) | D9: =SI([@SBAN]="";"";BUSCARV([@SBAN];Cronograma_Maestro!$A:$M;4;FALSO)) | E9: =SI([@SBAN]="";"";BUSCARV([@SBAN];Cronograma_Maestro!$A:$M;5;FALSO)) | F9: Edwin Santiago Cuchivaguen Diaz | G9: PMU COLSOF | H9: 46273 | I9: 46273 | L9: Programada | N9: =SI(O([@[Fecha_Programada_Inicio]]="";[@[Fecha_Inicio_Real]]="");"";SI([@[Fecha_Inicio_Real]]<=[@[Fecha_Programada_Inicio]];"SÍ";"NO")) | O9: =SI(O([@[Fecha_Programada_Fin]]="";[@[Fecha_Cierre_Operativo]]="");"";SI([@[Fecha_Cierre_Operativo]]<=SI([@[Fecha_Nueva_Programada]]<>"";[@[Fecha_Nueva_Programada]];[@[Fecha_Programada_Fin]]);"SÍ";"NO")) | P9: =SI(O([@[Cumpli_Ingreso]]="";[@[Cumpli_Salida]]="");"";SI(Y([@[Cumpli_Ingreso]]="SÍ";[@[Cumpli_Salida]]="SÍ");"SÍ";"NO")) | Q9: =SI(O([@[Fecha_Programada_Fin]]="";[@[Fecha_Cierre_Operativo]]="");"";MAX(0;ENTERO([@[Fecha_Cierre_Operativo]])-ENTERO(SI([@[Fecha_Nueva_Programada]]<>"";[@[Fecha_Nueva_Programada]];[@[Fecha_Programada_Fin]]))) | U9: 32 | W9: =SI.ERROR(SI(O([@[Fecha_Programada_Inicio]]="";[@[Fecha_Programada_Fin]]="");"";SI(Y([@[Fecha_Programada_Fin]]>=[@[Fecha_Programada_Inicio]];SI([@[Fecha_Cierre_Operativo]]="";VERDADERO;[@[Fecha_Cierre_Operativo]]>=[@[Fecha_Inicio_Real]]);SI([@[Fecha_Cierre_Administrativo]]="";VERDADERO;Y([@[Fecha_Cierre_Operativo]]<>"";[@[Fecha_Cierre_Administrativo]]>=[@[Fecha_Cierre_Operativo]])));"OK";"REVISAR"));"REVISAR") | X9: =SI([@SBAN]="";"";BUSCARV([@SBAN];Cronograma_Maestro!$A:$M;6;FALSO))
A10: 360 | B10: =SI([@SBAN]="";"";BUSCARV([@SBAN];Cronograma_Maestro!$A:$M;2;FALSO)) | C10: =SI([@SBAN]="";"";BUSCARV([@SBAN];Cronograma_Maestro!$A:$M;3;FALSO)) | D10: =SI([@SBAN]="";"";BUSCARV([@SBAN];Cronograma_Maestro!$A:$M;4;FALSO)) | E10: =SI([@SBAN]="";"";BUSCARV([@SBAN];Cronograma_Maestro!$A:$M;5;FALSO)) | F10: Anderson Forero Mora | G10: PMU COLSOF | H10: 46318 | I10: 46318 | L10: Programada | N10: =SI(O([@[Fecha_Programada_Inicio]]="";[@[Fecha_Inicio_Real]]="");"";SI([@[Fecha_Inicio_Real]]<=[@[Fecha_Programada_Inicio]];"SÍ";"NO")) | O10: =SI(O([@[Fecha_Programada_Fin]]="";[@[Fecha_Cierre_Operativo]]="");"";SI([@[Fecha_Cierre_Operativo]]<=SI([@[Fecha_Nueva_Programada]]<>"";[@[Fecha_Nueva_Programada]];[@[Fecha_Programada_Fin]]);"SÍ";"NO")) | P10: =SI(O([@[Cumpli_Ingreso]]="";[@[Cumpli_Salida]]="");"";SI(Y([@[Cumpli_Ingreso]]="SÍ";[@[Cumpli_Salida]]="SÍ");"SÍ";"NO")) | Q10: =SI(O([@[Fecha_Programada_Fin]]="";[@[Fecha_Cierre_Operativo]]="");"";MAX(0;ENTERO([@[Fecha_Cierre_Operativo]])-ENTERO(SI([@[Fecha_Nueva_Programada]]<>"";[@[Fecha_Nueva_Programada]];[@[Fecha_Programada_Fin]]))) | U10: 23 | W10: =SI.ERROR(SI(O([@[Fecha_Programada_Inicio]]="";[@[Fecha_Programada_Fin]]="");"";SI(Y([@[Fecha_Programada_Fin]]>=[@[Fecha_Programada_Inicio]];SI([@[Fecha_Cierre_Operativo]]="";VERDADERO;[@[Fecha_Cierre_Operativo]]>=[@[Fecha_Inicio_Real]]);SI([@[Fecha_Cierre_Administrativo]]="";VERDADERO;Y([@[Fecha_Cierre_Operativo]]<>"";[@[Fecha_Cierre_Administrativo]]>=[@[Fecha_Cierre_Operativo]])));"OK";"REVISAR"));"REVISAR") | X10: =SI([@SBAN]="";"";BUSCARV([@SBAN];Cronograma_Maestro!$A:$M;6;FALSO))
A11: 590 | B11: =SI([@SBAN]="";"";BUSCARV([@SBAN];Cronograma_Maestro!$A:$M;2;FALSO)) | C11: =SI([@SBAN]="";"";BUSCARV([@SBAN];Cronograma_Maestro!$A:$M;3;FALSO)) | D11: =SI([@SBAN]="";"";BUSCARV([@SBAN];Cronograma_Maestro!$A:$M;4;FALSO)) | E11: =SI([@SBAN]="";"";BUSCARV([@SBAN];Cronograma_Maestro!$A:$M;5;FALSO)) | F11: Anderson Forero Mora | G11: PMU COLSOF | H11: 46310 | I11: 46311 | L11: Programada | N11: =SI(O([@[Fecha_Programada_Inicio]]="";[@[Fecha_Inicio_Real]]="");"";SI([@[Fecha_Inicio_Real]]<=[@[Fecha_Programada_Inicio]];"SÍ";"NO")) | O11: =SI(O([@[Fecha_Programada_Fin]]="";[@[Fecha_Cierre_Operativo]]="");"";SI([@[Fecha_Cierre_Operativo]]<=SI([@[Fecha_Nueva_Programada]]<>"";[@[Fecha_Nueva_Programada]];[@[Fecha_Programada_Fin]]);"SÍ";"NO")) | P11: =SI(O([@[Cumpli_Ingreso]]="";[@[Cumpli_Salida]]="");"";SI(Y([@[Cumpli_Ingreso]]="SÍ";[@[Cumpli_Salida]]="SÍ");"SÍ";"NO")) | Q11: =SI(O([@[Fecha_Programada_Fin]]="";[@[Fecha_Cierre_Operativo]]="");"";MAX(0;ENTERO([@[Fecha_Cierre_Operativo]])-ENTERO(SI([@[Fecha_Nueva_Programada]]<>"";[@[Fecha_Nueva_Programada]];[@[Fecha_Programada_Fin]]))) | U11: 32 | W11: =SI.ERROR(SI(O([@[Fecha_Programada_Inicio]]="";[@[Fecha_Programada_Fin]]="");"";SI(Y([@[Fecha_Programada_Fin]]>=[@[Fecha_Programada_Inicio]];SI([@[Fecha_Cierre_Operativo]]="";VERDADERO;[@[Fecha_Cierre_Operativo]]>=[@[Fecha_Inicio_Real]]);SI([@[Fecha_Cierre_Administrativo]]="";VERDADERO;Y([@[Fecha_Cierre_Operativo]]<>"";[@[Fecha_Cierre_Administrativo]]>=[@[Fecha_Cierre_Operativo]])));"OK";"REVISAR"));"REVISAR") | X11: =SI([@SBAN]="";"";BUSCARV([@SBAN];Cronograma_Maestro!$A:$M;6;FALSO))
A12: 700 | B12: =SI([@SBAN]="";"";BUSCARV([@SBAN];Cronograma_Maestro!$A:$M;2;FALSO)) | C12: =SI([@SBAN]="";"";BUSCARV([@SBAN];Cronograma_Maestro!$A:$M;3;FALSO)) | D12: =SI([@SBAN]="";"";BUSCARV([@SBAN];Cronograma_Maestro!$A:$M;4;FALSO)) | E12: =SI([@SBAN]="";"";BUSCARV([@SBAN];Cronograma_Maestro!$A:$M;5;FALSO)) | F12: Edwin Santiago Cuchivaguen Diaz | G12: PMU COLSOF | H12: 46280 | I12: 46280 | L12: Programada | N12: =SI(O([@[Fecha_Programada_Inicio]]="";[@[Fecha_Inicio_Real]]="");"";SI([@[Fecha_Inicio_Real]]<=[@[Fecha_Programada_Inicio]];"SÍ";"NO")) | O12: =SI(O([@[Fecha_Programada_Fin]]="";[@[Fecha_Cierre_Operativo]]="");"";SI([@[Fecha_Cierre_Operativo]]<=SI([@[Fecha_Nueva_Programada]]<>"";[@[Fecha_Nueva_Programada]];[@[Fecha_Programada_Fin]]);"SÍ";"NO")) | P12: =SI(O([@[Cumpli_Ingreso]]="";[@[Cumpli_Salida]]="");"";SI(Y([@[Cumpli_Ingreso]]="SÍ";[@[Cumpli_Salida]]="SÍ");"SÍ";"NO")) | Q12: =SI(O([@[Fecha_Programada_Fin]]="";[@[Fecha_Cierre_Operativo]]="");"";MAX(0;ENTERO([@[Fecha_Cierre_Operativo]])-ENTERO(SI([@[Fecha_Nueva_Programada]]<>"";[@[Fecha_Nueva_Programada]];[@[Fecha_Programada_Fin]]))) | U12: 17 | W12: =SI.ERROR(SI(O([@[Fecha_Programada_Inicio]]="";[@[Fecha_Programada_Fin]]="");"";SI(Y([@[Fecha_Programada_Fin]]>=[@[Fecha_Programada_Inicio]];SI([@[Fecha_Cierre_Operativo]]="";VERDADERO;[@[Fecha_Cierre_Operativo]]>=[@[Fecha_Inicio_Real]]);SI([@[Fecha_Cierre_Administrativo]]="";VERDADERO;Y([@[Fecha_Cierre_Operativo]]<>"";[@[Fecha_Cierre_Administrativo]]>=[@[Fecha_Cierre_Operativo]])));"OK";"REVISAR"));"REVISAR") | X12: =SI([@SBAN]="";"";BUSCARV([@SBAN];Cronograma_Maestro!$A:$M;6;FALSO))
A13: 730 | B13: =SI([@SBAN]="";"";BUSCARV([@SBAN];Cronograma_Maestro!$A:$M;2;FALSO)) | C13: =SI([@SBAN]="";"";BUSCARV([@SBAN];Cronograma_Maestro!$A:$M;3;FALSO)) | D13: =SI([@SBAN]="";"";BUSCARV([@SBAN];Cronograma_Maestro!$A:$M;4;FALSO)) | E13: =SI([@SBAN]="";"";BUSCARV([@SBAN];Cronograma_Maestro!$A:$M;5;FALSO)) | F13: Nelson Leonardo Paez Suarez | G13: PMU COLSOF | H13: 46274 | I13: 46274 | L13: Programada | N13: =SI(O([@[Fecha_Programada_Inicio]]="";[@[Fecha_Inicio_Real]]="");"";SI([@[Fecha_Inicio_Real]]<=[@[Fecha_Programada_Inicio]];"SÍ";"NO")) | O13: =SI(O([@[Fecha_Programada_Fin]]="";[@[Fecha_Cierre_Operativo]]="");"";SI([@[Fecha_Cierre_Operativo]]<=SI([@[Fecha_Nueva_Programada]]<>"";[@[Fecha_Nueva_Programada]];[@[Fecha_Programada_Fin]]);"SÍ";"NO")) | P13: =SI(O([@[Cumpli_Ingreso]]="";[@[Cumpli_Salida]]="");"";SI(Y([@[Cumpli_Ingreso]]="SÍ";[@[Cumpli_Salida]]="SÍ");"SÍ";"NO")) | Q13: =SI(O([@[Fecha_Programada_Fin]]="";[@[Fecha_Cierre_Operativo]]="");"";MAX(0;ENTERO([@[Fecha_Cierre_Operativo]])-ENTERO(SI([@[Fecha_Nueva_Programada]]<>"";[@[Fecha_Nueva_Programada]];[@[Fecha_Programada_Fin]]))) | U13: 14 | W13: =SI.ERROR(SI(O([@[Fecha_Programada_Inicio]]="";[@[Fecha_Programada_Fin]]="");"";SI(Y([@[Fecha_Programada_Fin]]>=[@[Fecha_Programada_Inicio]];SI([@[Fecha_Cierre_Operativo]]="";VERDADERO;[@[Fecha_Cierre_Operativo]]>=[@[Fecha_Inicio_Real]]);SI([@[Fecha_Cierre_Administrativo]]="";VERDADERO;Y([@[Fecha_Cierre_Operativo]]<>"";[@[Fecha_Cierre_Administrativo]]>=[@[Fecha_Cierre_Operativo]])));"OK";"REVISAR"));"REVISAR") | X13: =SI([@SBAN]="";"";BUSCARV([@SBAN];Cronograma_Maestro!$A:$M;6;FALSO))
... A54: 1320 | B54: =SI([@SBAN]="";"";BUSCARV([@SBAN];Cronograma_Maestro!$A:$M;2;FALSO)) | C54: =SI([@SBAN]="";"";BUSCARV([@SBAN];Cronograma_Maestro!$A:$M;3;FALSO)) | D54: =SI([@SBAN]="";"";BUSCARV([@SBAN];Cronograma_Maestro!$A:$M;4;FALSO)) | E54: =SI([@SBAN]="";"";BUSCARV([@SBAN];Cronograma_Maestro!$A:$M;5;FALSO)) | F54: Ever Enrique Esquivel Movilla | G54: PMU COLSOF | H54: 46272 | I54: 46272 | L54: Programada | N54: =SI(O([@[Fecha_Programada_Inicio]]="";[@[Fecha_Inicio_Real]]="");"";SI([@[Fecha_Inicio_Real]]<=[@[Fecha_Programada_Inicio]];"SÍ";"NO")) | O54: =SI(O([@[Fecha_Programada_Fin]]="";[@[Fecha_Cierre_Operativo]]="");"";SI([@[Fecha_Cierre_Operativo]]<=SI([@[Fecha_Nueva_Programada]]<>"";[@[Fecha_Nueva_Programada]];[@[Fecha_Programada_Fin]]);"SÍ";"NO")) | P54: =SI(O([@[Cumpli_Ingreso]]="";[@[Cumpli_Salida]]="");"";SI(Y([@[Cumpli_Ingreso]]="SÍ";[@[Cumpli_Salida]]="SÍ");"SÍ";"NO")) | Q54: =SI(O([@[Fecha_Programada_Fin]]="";[@[Fecha_Cierre_Operativo]]="");"";MAX(0;ENTERO([@[Fecha_Cierre_Operativo]])-ENTERO(SI([@[Fecha_Nueva_Programada]]<>"";[@[Fecha_Nueva_Programada]];[@[Fecha_Programada_Fin]]))) | U54: 23 | W54: =SI.ERROR(SI(O([@[Fecha_Programada_Inicio]]="";[@[Fecha_Programada_Fin]]="");"";SI(Y([@[Fecha_Programada_Fin]]>=[@[Fecha_Programada_Inicio]];SI([@[Fecha_Cierre_Operativo]]="";VERDADERO;[@[Fecha_Cierre_Operativo]]>=[@[Fecha_Inicio_Real]]);SI([@[Fecha_Cierre_Administrativo]]="";VERDADERO;Y([@[Fecha_Cierre_Operativo]]<>"";[@[Fecha_Cierre_Administrativo]]>=[@[Fecha_Cierre_Operativo]])));"OK";"REVISAR"));"REVISAR") | X54: =SI([@SBAN]="";"";BUSCARV([@SBAN];Cronograma_Maestro!$A:$M;6;FALSO))
A55: 1321 | B55: =SI([@SBAN]="";"";BUSCARV([@SBAN];Cronograma_Maestro!$A:$M;2;FALSO)) | C55: =SI([@SBAN]="";"";BUSCARV([@SBAN];Cronograma_Maestro!$A:$M;3;FALSO)) | D55: =SI([@SBAN]="";"";BUSCARV([@SBAN];Cronograma_Maestro!$A:$M;4;FALSO)) | E55: =SI([@SBAN]="";"";BUSCARV([@SBAN];Cronograma_Maestro!$A:$M;5;FALSO)) | F55: Ever Enrique Esquivel Movilla | G55: PMU COLSOF | H55: 46266 | I55: 46267 | J55: 46266 | L55: En Proceso | N55: =SI(O([@[Fecha_Programada_Inicio]]="";[@[Fecha_Inicio_Real]]="");"";SI([@[Fecha_Inicio_Real]]<=[@[Fecha_Programada_Inicio]];"SÍ";"NO")) | O55: =SI(O([@[Fecha_Programada_Fin]]="";[@[Fecha_Cierre_Operativo]]="");"";SI([@[Fecha_Cierre_Operativo]]<=SI([@[Fecha_Nueva_Programada]]<>"";[@[Fecha_Nueva_Programada]];[@[Fecha_Programada_Fin]]);"SÍ";"NO")) | P55: =SI(O([@[Cumpli_Ingreso]]="";[@[Cumpli_Salida]]="");"";SI(Y([@[Cumpli_Ingreso]]="SÍ";[@[Cumpli_Salida]]="SÍ");"SÍ";"NO")) | Q55: =SI(O([@[Fecha_Programada_Fin]]="";[@[Fecha_Cierre_Operativo]]="");"";MAX(0;ENTERO([@[Fecha_Cierre_Operativo]])-ENTERO(SI([@[Fecha_Nueva_Programada]]<>"";[@[Fecha_Nueva_Programada]];[@[Fecha_Programada_Fin]]))) | U55: 34 | V55: No firma el director debido en vacaiones, firma el encergado de la sede | W55: =SI.ERROR(SI(O([@[Fecha_Programada_Inicio]]="";[@[Fecha_Programada_Fin]]="");"";SI(Y([@[Fecha_Programada_Fin]]>=[@[Fecha_Programada_Inicio]];SI([@[Fecha_Cierre_Operativo]]="";VERDADERO;[@[Fecha_Cierre_Operativo]]>=[@[Fecha_Inicio_Real]]);SI([@[Fecha_Cierre_Administrativo]]="";VERDADERO;Y([@[Fecha_Cierre_Operativo]]<>"";[@[Fecha_Cierre_Administrativo]]>=[@[Fecha_Cierre_Operativo]])));"OK";"REVISAR"));"REVISAR") | X55: =SI([@SBAN]="";"";BUSCARV([@SBAN];Cronograma_Maestro!$A:$M;6;FALSO))
A56: 1323 | B56: =SI([@SBAN]="";"";BUSCARV([@SBAN];Cronograma_Maestro!$A:$M;2;FALSO)) | C56: =SI([@SBAN]="";"";BUSCARV([@SBAN];Cronograma_Maestro!$A:$M;3;FALSO)) | D56: =SI([@SBAN]="";"";BUSCARV([@SBAN];Cronograma_Maestro!$A:$M;4;FALSO)) | E56: =SI([@SBAN]="";"";BUSCARV([@SBAN];Cronograma_Maestro!$A:$M;5;FALSO)) | F56: Andrés Mariano Bustamante Castro | G56: PMU COLSOF | H56: 46297 | I56: 46304 | L56: Programada | N56: =SI(O([@[Fecha_Programada_Inicio]]="";[@[Fecha_Inicio_Real]]="");"";SI([@[Fecha_Inicio_Real]]<=[@[Fecha_Programada_Inicio]];"SÍ";"NO")) | O56: =SI(O([@[Fecha_Programada_Fin]]="";[@[Fecha_Cierre_Operativo]]="");"";SI([@[Fecha_Cierre_Operativo]]<=SI([@[Fecha_Nueva_Programada]]<>"";[@[Fecha_Nueva_Programada]];[@[Fecha_Programada_Fin]]);"SÍ";"NO")) | P56: =SI(O([@[Cumpli_Ingreso]]="";[@[Cumpli_Salida]]="");"";SI(Y([@[Cumpli_Ingreso]]="SÍ";[@[Cumpli_Salida]]="SÍ");"SÍ";"NO")) | Q56: =SI(O([@[Fecha_Programada_Fin]]="";[@[Fecha_Cierre_Operativo]]="");"";MAX(0;ENTERO([@[Fecha_Cierre_Operativo]])-ENTERO(SI([@[Fecha_Nueva_Programada]]<>"";[@[Fecha_Nueva_Programada]];[@[Fecha_Programada_Fin]]))) | U56: 40 | W56: =SI.ERROR(SI(O([@[Fecha_Programada_Inicio]]="";[@[Fecha_Programada_Fin]]="");"";SI(Y([@[Fecha_Programada_Fin]]>=[@[Fecha_Programada_Inicio]];SI([@[Fecha_Cierre_Operativo]]="";VERDADERO;[@[Fecha_Cierre_Operativo]]>=[@[Fecha_Inicio_Real]]);SI([@[Fecha_Cierre_Administrativo]]="";VERDADERO;Y([@[Fecha_Cierre_Operativo]]<>"";[@[Fecha_Cierre_Administrativo]]>=[@[Fecha_Cierre_Operativo]])));"OK";"REVISAR"));"REVISAR") | X56: =SI([@SBAN]="";"";BUSCARV([@SBAN];Cronograma_Maestro!$A:$M;6;FALSO))
A57: 1324 | B57: =SI([@SBAN]="";"";BUSCARV([@SBAN];Cronograma_Maestro!$A:$M;2;FALSO)) | C57: =SI([@SBAN]="";"";BUSCARV([@SBAN];Cronograma_Maestro!$A:$M;3;FALSO)) | D57: =SI([@SBAN]="";"";BUSCARV([@SBAN];Cronograma_Maestro!$A:$M;4;FALSO)) | E57: =SI([@SBAN]="";"";BUSCARV([@SBAN];Cronograma_Maestro!$A:$M;5;FALSO)) | F57: Andrés Mariano Bustamante Castro | G57: PMU COLSOF | H57: 46309 | I57: 46309 | L57: Programada | N57: =SI(O([@[Fecha_Programada_Inicio]]="";[@[Fecha_Inicio_Real]]="");"";SI([@[Fecha_Inicio_Real]]<=[@[Fecha_Programada_Inicio]];"SÍ";"NO")) | O57: =SI(O([@[Fecha_Programada_Fin]]="";[@[Fecha_Cierre_Operativo]]="");"";SI([@[Fecha_Cierre_Operativo]]<=SI([@[Fecha_Nueva_Programada]]<>"";[@[Fecha_Nueva_Programada]];[@[Fecha_Programada_Fin]]);"SÍ";"NO")) | P57: =SI(O([@[Cumpli_Ingreso]]="";[@[Cumpli_Salida]]="");"";SI(Y([@[Cumpli_Ingreso]]="SÍ";[@[Cumpli_Salida]]="SÍ");"SÍ";"NO")) | Q57: =SI(O([@[Fecha_Programada_Fin]]="";[@[Fecha_Cierre_Operativo]]="");"";MAX(0;ENTERO([@[Fecha_Cierre_Operativo]])-ENTERO(SI([@[Fecha_Nueva_Programada]]<>"";[@[Fecha_Nueva_Programada]];[@[Fecha_Programada_Fin]]))) | U57: 15 | W57: =SI.ERROR(SI(O([@[Fecha_Programada_Inicio]]="";[@[Fecha_Programada_Fin]]="");"";SI(Y([@[Fecha_Programada_Fin]]>=[@[Fecha_Programada_Inicio]];SI([@[Fecha_Cierre_Operativo]]="";VERDADERO;[@[Fecha_Cierre_Operativo]]>=[@[Fecha_Inicio_Real]]);SI([@[Fecha_Cierre_Administrativo]]="";VERDADERO;Y([@[Fecha_Cierre_Operativo]]<>"";[@[Fecha_Cierre_Administrativo]]>=[@[Fecha_Cierre_Operativo]])));"OK";"REVISAR"));"REVISAR") | X57: =SI([@SBAN]="";"";BUSCARV([@SBAN];Cronograma_Maestro!$A:$M;6;FALSO))
A58: 1325 | B58: =SI([@SBAN]="";"";BUSCARV([@SBAN];Cronograma_Maestro!$A:$M;2;FALSO)) | C58: =SI([@SBAN]="";"";BUSCARV([@SBAN];Cronograma_Maestro!$A:$M;3;FALSO)) | D58: =SI([@SBAN]="";"";BUSCARV([@SBAN];Cronograma_Maestro!$A:$M;4;FALSO)) | E58: =SI([@SBAN]="";"";BUSCARV([@SBAN];Cronograma_Maestro!$A:$M;5;FALSO)) | F58: Ever Enrique Esquivel Movilla | G58: PMU COLSOF | H58: 46276 | I58: 46276 | L58: Programada | N58: =SI(O([@[Fecha_Programada_Inicio]]="";[@[Fecha_Inicio_Real]]="");"";SI([@[Fecha_Inicio_Real]]<=[@[Fecha_Programada_Inicio]];"SÍ";"NO")) | O58: =SI(O([@[Fecha_Programada_Fin]]="";[@[Fecha_Cierre_Operativo]]="");"";SI([@[Fecha_Cierre_Operativo]]<=SI([@[Fecha_Nueva_Programada]]<>"";[@[Fecha_Nueva_Programada]];[@[Fecha_Programada_Fin]]);"SÍ";"NO")) | P58: =SI(O([@[Cumpli_Ingreso]]="";[@[Cumpli_Salida]]="");"";SI(Y([@[Cumpli_Ingreso]]="SÍ";[@[Cumpli_Salida]]="SÍ");"SÍ";"NO")) | Q58: =SI(O([@[Fecha_Programada_Fin]]="";[@[Fecha_Cierre_Operativo]]="");"";MAX(0;ENTERO([@[Fecha_Cierre_Operativo]])-ENTERO(SI([@[Fecha_Nueva_Programada]]<>"";[@[Fecha_Nueva_Programada]];[@[Fecha_Programada_Fin]]))) | U58: 29 | W58: =SI.ERROR(SI(O([@[Fecha_Programada_Inicio]]="";[@[Fecha_Programada_Fin]]="");"";SI(Y([@[Fecha_Programada_Fin]]>=[@[Fecha_Programada_Inicio]];SI([@[Fecha_Cierre_Operativo]]="";VERDADERO;[@[Fecha_Cierre_Operativo]]>=[@[Fecha_Inicio_Real]]);SI([@[Fecha_Cierre_Administrativo]]="";VERDADERO;Y([@[Fecha_Cierre_Operativo]]<>"";[@[Fecha_Cierre_Administrativo]]>=[@[Fecha_Cierre_Operativo]])));"OK";"REVISAR"));"REVISAR") | X58: =SI([@SBAN]="";"";BUSCARV([@SBAN];Cronograma_Maestro!$A:$M;6;FALSO))
A59: 1326 | B59: =SI([@SBAN]="";"";BUSCARV([@SBAN];Cronograma_Maestro!$A:$M;2;FALSO)) | C59: =SI([@SBAN]="";"";BUSCARV([@SBAN];Cronograma_Maestro!$A:$M;3;FALSO)) | D59: =SI([@SBAN]="";"";BUSCARV([@SBAN];Cronograma_Maestro!$A:$M;4;FALSO)) | E59: =SI([@SBAN]="";"";BUSCARV([@SBAN];Cronograma_Maestro!$A:$M;5;FALSO)) | F59: Ever Enrique Esquivel Movilla | G59: PMU COLSOF | H59: 46279 | I59: 46279 | L59: Programada | N59: =SI(O([@[Fecha_Programada_Inicio]]="";[@[Fecha_Inicio_Real]]="");"";SI([@[Fecha_Inicio_Real]]<=[@[Fecha_Programada_Inicio]];"SÍ";"NO")) | O59: =SI(O([@[Fecha_Programada_Fin]]="";[@[Fecha_Cierre_Operativo]]="");"";SI([@[Fecha_Cierre_Operativo]]<=SI([@[Fecha_Nueva_Programada]]<>"";[@[Fecha_Nueva_Programada]];[@[Fecha_Programada_Fin]]);"SÍ";"NO")) | P59: =SI(O([@[Cumpli_Ingreso]]="";[@[Cumpli_Salida]]="");"";SI(Y([@[Cumpli_Ingreso]]="SÍ";[@[Cumpli_Salida]]="SÍ");"SÍ";"NO")) | Q59: =SI(O([@[Fecha_Programada_Fin]]="";[@[Fecha_Cierre_Operativo]]="");"";MAX(0;ENTERO([@[Fecha_Cierre_Operativo]])-ENTERO(SI([@[Fecha_Nueva_Programada]]<>"";[@[Fecha_Nueva_Programada]];[@[Fecha_Programada_Fin]]))) | U59: 14 | W59: =SI.ERROR(SI(O([@[Fecha_Programada_Inicio]]="";[@[Fecha_Programada_Fin]]="");"";SI(Y([@[Fecha_Programada_Fin]]>=[@[Fecha_Programada_Inicio]];SI([@[Fecha_Cierre_Operativo]]="";VERDADERO;[@[Fecha_Cierre_Operativo]]>=[@[Fecha_Inicio_Real]]);SI([@[Fecha_Cierre_Administrativo]]="";VERDADERO;Y([@[Fecha_Cierre_Operativo]]<>"";[@[Fecha_Cierre_Administrativo]]>=[@[Fecha_Cierre_Operativo]])));"OK";"REVISAR"));"REVISAR") | X59: =SI([@SBAN]="";"";BUSCARV([@SBAN];Cronograma_Maestro!$A:$M;6;FALSO))
A60: 1330 | B60: =SI([@SBAN]="";"";BUSCARV([@SBAN];Cronograma_Maestro!$A:$M;2;FALSO)) | C60: =SI([@SBAN]="";"";BUSCARV([@SBAN];Cronograma_Maestro!$A:$M;3;FALSO)) | D60: =SI([@SBAN]="";"";BUSCARV([@SBAN];Cronograma_Maestro!$A:$M;4;FALSO)) | E60: =SI([@SBAN]="";"";BUSCARV([@SBAN];Cronograma_Maestro!$A:$M;5;FALSO)) | F60: Juan Pablo Osorio Ramirez | G60: PMU COLSOF | H60: 46309 | I60: 46309 | L60: Programada | N60: =SI(O([@[Fecha_Programada_Inicio]]="";[@[Fecha_Inicio_Real]]="");"";SI([@[Fecha_Inicio_Real]]<=[@[Fecha_Programada_Inicio]];"SÍ";"NO")) | O60: =SI(O([@[Fecha_Programada_Fin]]="";[@[Fecha_Cierre_Operativo]]="");"";SI([@[Fecha_Cierre_Operativo]]<=SI([@[Fecha_Nueva_Programada]]<>"";[@[Fecha_Nueva_Programada]];[@[Fecha_Programada_Fin]]);"SÍ";"NO")) | P60: =SI(O([@[Cumpli_Ingreso]]="";[@[Cumpli_Salida]]="");"";SI(Y([@[Cumpli_Ingreso]]="SÍ";[@[Cumpli_Salida]]="SÍ");"SÍ";"NO")) | Q60: =SI(O([@[Fecha_Programada_Fin]]="";[@[Fecha_Cierre_Operativo]]="");"";MAX(0;ENTERO([@[Fecha_Cierre_Operativo]])-ENTERO(SI([@[Fecha_Nueva_Programada]]<>"";[@[Fecha_Nueva_Programada]];[@[Fecha_Programada_Fin]]))) | U60: 12 | W60: =SI.ERROR(SI(O([@[Fecha_Programada_Inicio]]="";[@[Fecha_Programada_Fin]]="");"";SI(Y([@[Fecha_Programada_Fin]]>=[@[Fecha_Programada_Inicio]];SI([@[Fecha_Cierre_Operativo]]="";VERDADERO;[@[Fecha_Cierre_Operativo]]>=[@[Fecha_Inicio_Real]]);SI([@[Fecha_Cierre_Administrativo]]="";VERDADERO;Y([@[Fecha_Cierre_Operativo]]<>"";[@[Fecha_Cierre_Administrativo]]>=[@[Fecha_Cierre_Operativo]])));"OK";"REVISAR"));"REVISAR") | X60: =SI([@SBAN]="";"";BUSCARV([@SBAN];Cronograma_Maestro!$A:$M;6;FALSO))
A61: 1331 | B61: =SI([@SBAN]="";"";BUSCARV([@SBAN];Cronograma_Maestro!$A:$M;2;FALSO)) | C61: =SI([@SBAN]="";"";BUSCARV([@SBAN];Cronograma_Maestro!$A:$M;3;FALSO)) | D61: =SI([@SBAN]="";"";BUSCARV([@SBAN];Cronograma_Maestro!$A:$M;4;FALSO)) | E61: =SI([@SBAN]="";"";BUSCARV([@SBAN];Cronograma_Maestro!$A:$M;5;FALSO)) | F61: Andrés Mariano Bustamante Castro | G61: PMU COLSOF | H61: 46294 | I61: 46296 | L61: Programada | N61: =SI(O([@[Fecha_Programada_Inicio]]="";[@[Fecha_Inicio_Real]]="");"";SI([@[Fecha_Inicio_Real]]<=[@[Fecha_Programada_Inicio]];"SÍ";"NO")) | O61: =SI(O([@[Fecha_Programada_Fin]]="";[@[Fecha_Cierre_Operativo]]="");"";SI([@[Fecha_Cierre_Operativo]]<=SI([@[Fecha_Nueva_Programada]]<>"";[@[Fecha_Nueva_Programada]];[@[Fecha_Programada_Fin]]);"SÍ";"NO")) | P61: =SI(O([@[Cumpli_Ingreso]]="";[@[Cumpli_Salida]]="");"";SI(Y([@[Cumpli_Ingreso]]="SÍ";[@[Cumpli_Salida]]="SÍ");"SÍ";"NO")) | Q61: =SI(O([@[Fecha_Programada_Fin]]="";[@[Fecha_Cierre_Operativo]]="");"";MAX(0;ENTERO([@[Fecha_Cierre_Operativo]])-ENTERO(SI([@[Fecha_Nueva_Programada]]<>"";[@[Fecha_Nueva_Programada]];[@[Fecha_Programada_Fin]]))) | U61: 28 | W61: =SI.ERROR(SI(O([@[Fecha_Programada_Inicio]]="";[@[Fecha_Programada_Fin]]="");"";SI(Y([@[Fecha_Programada_Fin]]>=[@[Fecha_Programada_Inicio]];SI([@[Fecha_Cierre_Operativo]]="";VERDADERO;[@[Fecha_Cierre_Operativo]]>=[@[Fecha_Inicio_Real]]);SI([@[Fecha_Cierre_Administrativo]]="";VERDADERO;Y([@[Fecha_Cierre_Operativo]]<>"";[@[Fecha_Cierre_Administrativo]]>=[@[Fecha_Cierre_Operativo]])));"OK";"REVISAR"));"REVISAR") | X61: =SI([@SBAN]="";"";BUSCARV([@SBAN];Cronograma_Maestro!$A:$M;6;FALSO))
A62: 1332 | B62: =SI([@SBAN]="";"";BUSCARV([@SBAN];Cronograma_Maestro!$A:$M;2;FALSO)) | C62: =SI([@SBAN]="";"";BUSCARV([@SBAN];Cronograma_Maestro!$A:$M;3;FALSO)) | D62: =SI([@SBAN]="";"";BUSCARV([@SBAN];Cronograma_Maestro!$A:$M;4;FALSO)) | E62: =SI([@SBAN]="";"";BUSCARV([@SBAN];Cronograma_Maestro!$A:$M;5;FALSO)) | F62: Ever Enrique Esquivel Movilla | G62: PMU COLSOF | H62: 46286 | I62: 46286 | L62: Programada | N62: =SI(O([@[Fecha_Programada_Inicio]]="";[@[Fecha_Inicio_Real]]="");"";SI([@[Fecha_Inicio_Real]]<=[@[Fecha_Programada_Inicio]];"SÍ";"NO")) | O62: =SI(O([@[Fecha_Programada_Fin]]="";[@[Fecha_Cierre_Operativo]]="");"";SI([@[Fecha_Cierre_Operativo]]<=SI([@[Fecha_Nueva_Programada]]<>"";[@[Fecha_Nueva_Programada]];[@[Fecha_Programada_Fin]]);"SÍ";"NO")) | P62: =SI(O([@[Cumpli_Ingreso]]="";[@[Cumpli_Salida]]="");"";SI(Y([@[Cumpli_Ingreso]]="SÍ";[@[Cumpli_Salida]]="SÍ");"SÍ";"NO")) | Q62: =SI(O([@[Fecha_Programada_Fin]]="";[@[Fecha_Cierre_Operativo]]="");"";MAX(0;ENTERO([@[Fecha_Cierre_Operativo]])-ENTERO(SI([@[Fecha_Nueva_Programada]]<>"";[@[Fecha_Nueva_Programada]];[@[Fecha_Programada_Fin]]))) | U62: 25 | W62: =SI.ERROR(SI(O([@[Fecha_Programada_Inicio]]="";[@[Fecha_Programada_Fin]]="");"";SI(Y([@[Fecha_Programada_Fin]]>=[@[Fecha_Programada_Inicio]];SI([@[Fecha_Cierre_Operativo]]="";VERDADERO;[@[Fecha_Cierre_Operativo]]>=[@[Fecha_Inicio_Real]]);SI([@[Fecha_Cierre_Administrativo]]="";VERDADERO;Y([@[Fecha_Cierre_Operativo]]<>"";[@[Fecha_Cierre_Administrativo]]>=[@[Fecha_Cierre_Operativo]])));"OK";"REVISAR"));"REVISAR") | X62: =SI([@SBAN]="";"";BUSCARV([@SBAN];Cronograma_Maestro!$A:$M;6;FALSO))
A63: 1334 | B63: =SI([@SBAN]="";"";BUSCARV([@SBAN];Cronograma_Maestro!$A:$M;2;FALSO)) | C63: =SI([@SBAN]="";"";BUSCARV([@SBAN];Cronograma_Maestro!$A:$M;3;FALSO)) | D63: =SI([@SBAN]="";"";BUSCARV([@SBAN];Cronograma_Maestro!$A:$M;4;FALSO)) | E63: =SI([@SBAN]="";"";BUSCARV([@SBAN];Cronograma_Maestro!$A:$M;5;FALSO)) | F63: Juan Pablo Osorio Ramirez | G63: PMU COLSOF | H63: 46274 | I63: 46274 | L63: Programada | N63: =SI(O([@[Fecha_Programada_Inicio]]="";[@[Fecha_Inicio_Real]]="");"";SI([@[Fecha_Inicio_Real]]<=[@[Fecha_Programada_Inicio]];"SÍ";"NO")) | O63: =SI(O([@[Fecha_Programada_Fin]]="";[@[Fecha_Cierre_Operativo]]="");"";SI([@[Fecha_Cierre_Operativo]]<=SI([@[Fecha_Nueva_Programada]]<>"";[@[Fecha_Nueva_Programada]];[@[Fecha_Programada_Fin]]);"SÍ";"NO")) | P63: =SI(O([@[Cumpli_Ingreso]]="";[@[Cumpli_Salida]]="");"";SI(Y([@[Cumpli_Ingreso]]="SÍ";[@[Cumpli_Salida]]="SÍ");"SÍ";"NO")) | Q63: =SI(O([@[Fecha_Programada_Fin]]="";[@[Fecha_Cierre_Operativo]]="");"";MAX(0;ENTERO([@[Fecha_Cierre_Operativo]])-ENTERO(SI([@[Fecha_Nueva_Programada]]<>"";[@[Fecha_Nueva_Programada]];[@[Fecha_Programada_Fin]]))) | U63: 16 | W63: =SI.ERROR(SI(O([@[Fecha_Programada_Inicio]]="";[@[Fecha_Programada_Fin]]="");"";SI(Y([@[Fecha_Programada_Fin]]>=[@[Fecha_Programada_Inicio]];SI([@[Fecha_Cierre_Operativo]]="";VERDADERO;[@[Fecha_Cierre_Operativo]]>=[@[Fecha_Inicio_Real]]);SI([@[Fecha_Cierre_Administrativo]]="";VERDADERO;Y([@[Fecha_Cierre_Operativo]]<>"";[@[Fecha_Cierre_Administrativo]]>=[@[Fecha_Cierre_Operativo]])));"OK";"REVISAR"));"REVISAR") | X63: =SI([@SBAN]="";"";BUSCARV([@SBAN];Cronograma_Maestro!$A:$M;6;FALSO))
A64: 1336 | B64: =SI([@SBAN]="";"";BUSCARV([@SBAN];Cronograma_Maestro!$A:$M;2;FALSO)) | C64: =SI([@SBAN]="";"";BUSCARV([@SBAN];Cronograma_Maestro!$A:$M;3;FALSO)) | D64: =SI([@SBAN]="";"";BUSCARV([@SBAN];Cronograma_Maestro!$A:$M;4;FALSO)) | E64: =SI([@SBAN]="";"";BUSCARV([@SBAN];Cronograma_Maestro!$A:$M;5;FALSO)) | F64: Juan Pablo Osorio Ramirez | G64: PMU COLSOF | H64: 46276 | I64: 46276 | L64: Programada | N64: =SI(O([@[Fecha_Programada_Inicio]]="";[@[Fecha_Inicio_Real]]="");"";SI([@[Fecha_Inicio_Real]]<=[@[Fecha_Programada_Inicio]];"SÍ";"NO")) | O64: =SI(O([@[Fecha_Programada_Fin]]="";[@[Fecha_Cierre_Operativo]]="");"";SI([@[Fecha_Cierre_Operativo]]<=SI([@[Fecha_Nueva_Programada]]<>"";[@[Fecha_Nueva_Programada]];[@[Fecha_Programada_Fin]]);"SÍ";"NO")) | P64: =SI(O([@[Cumpli_Ingreso]]="";[@[Cumpli_Salida]]="");"";SI(Y([@[Cumpli_Ingreso]]="SÍ";[@[Cumpli_Salida]]="SÍ");"SÍ";"NO")) | Q64: =SI(O([@[Fecha_Programada_Fin]]="";[@[Fecha_Cierre_Operativo]]="");"";MAX(0;ENTERO([@[Fecha_Cierre_Operativo]])-ENTERO(SI([@[Fecha_Nueva_Programada]]<>"";[@[Fecha_Nueva_Programada]];[@[Fecha_Programada_Fin]]))) | U64: 14 | W64: =SI.ERROR(SI(O([@[Fecha_Programada_Inicio]]="";[@[Fecha_Programada_Fin]]="");"";SI(Y([@[Fecha_Programada_Fin]]>=[@[Fecha_Programada_Inicio]];SI([@[Fecha_Cierre_Operativo]]="";VERDADERO;[@[Fecha_Cierre_Operativo]]>=[@[Fecha_Inicio_Real]]);SI([@[Fecha_Cierre_Administrativo]]="";VERDADERO;Y([@[Fecha_Cierre_Operativo]]<>"";[@[Fecha_Cierre_Administrativo]]>=[@[Fecha_Cierre_Operativo]])));"OK";"REVISAR"));"REVISAR") | X64: =SI([@SBAN]="";"";BUSCARV([@SBAN];Cronograma_Maestro!$A:$M;6;FALSO))
A65: 1340 | B65: =SI([@SBAN]="";"";BUSCARV([@SBAN];Cronograma_Maestro!$A:$M;2;FALSO)) | C65: =SI([@SBAN]="";"";BUSCARV([@SBAN];Cronograma_Maestro!$A:$M;3;FALSO)) | D65: =SI([@SBAN]="";"";BUSCARV([@SBAN];Cronograma_Maestro!$A:$M;4;FALSO)) | E65: =SI([@SBAN]="";"";BUSCARV([@SBAN];Cronograma_Maestro!$A:$M;5;FALSO)) | F65: Juan Pablo Osorio Ramirez | G65: PMU COLSOF | H65: 46314 | I65: 46314 | L65: Programada | N65: =SI(O([@[Fecha_Programada_Inicio]]="";[@[Fecha_Inicio_Real]]="");"";SI([@[Fecha_Inicio_Real]]<=[@[Fecha_Programada_Inicio]];"SÍ";"NO")) | O65: =SI(O([@[Fecha_Programada_Fin]]="";[@[Fecha_Cierre_Operativo]]="");"";SI([@[Fecha_Cierre_Operativo]]<=SI([@[Fecha_Nueva_Programada]]<>"";[@[Fecha_Nueva_Programada]];[@[Fecha_Programada_Fin]]);"SÍ";"NO")) | P65: =SI(O([@[Cumpli_Ingreso]]="";[@[Cumpli_Salida]]="");"";SI(Y([@[Cumpli_Ingreso]]="SÍ";[@[Cumpli_Salida]]="SÍ");"SÍ";"NO")) | Q65: =SI(O([@[Fecha_Programada_Fin]]="";[@[Fecha_Cierre_Operativo]]="");"";MAX(0;ENTERO([@[Fecha_Cierre_Operativo]])-ENTERO(SI([@[Fecha_Nueva_Programada]]<>"";[@[Fecha_Nueva_Programada]];[@[Fecha_Programada_Fin]]))) | U65: 27 | W65: =SI.ERROR(SI(O([@[Fecha_Programada_Inicio]]="";[@[Fecha_Programada_Fin]]="");"";SI(Y([@[Fecha_Programada_Fin]]>=[@[Fecha_Programada_Inicio]];SI([@[Fecha_Cierre_Operativo]]="";VERDADERO;[@[Fecha_Cierre_Operativo]]>=[@[Fecha_Inicio_Real]]);SI([@[Fecha_Cierre_Administrativo]]="";VERDADERO;Y([@[Fecha_Cierre_Operativo]]<>"";[@[Fecha_Cierre_Administrativo]]>=[@[Fecha_Cierre_Operativo]])));"OK";"REVISAR"));"REVISAR") | X65: =SI([@SBAN]="";"";BUSCARV([@SBAN];Cronograma_Maestro!$A:$M;6;FALSO))
A66: 1341 | B66: =SI([@SBAN]="";"";BUSCARV([@SBAN];Cronograma_Maestro!$A:$M;2;FALSO)) | C66: =SI([@SBAN]="";"";BUSCARV([@SBAN];Cronograma_Maestro!$A:$M;3;FALSO)) | D66: =SI([@SBAN]="";"";BUSCARV([@SBAN];Cronograma_Maestro!$A:$M;4;FALSO)) | E66: =SI([@SBAN]="";"";BUSCARV([@SBAN];Cronograma_Maestro!$A:$M;5;FALSO)) | F66: Juan Pablo Osorio Ramirez | G66: PMU COLSOF | H66: 46275 | I66: 46275 | L66: Programada | N66: =SI(O([@[Fecha_Programada_Inicio]]="";[@[Fecha_Inicio_Real]]="");"";SI([@[Fecha_Inicio_Real]]<=[@[Fecha_Programada_Inicio]];"SÍ";"NO")) | O66: =SI(O([@[Fecha_Programada_Fin]]="";[@[Fecha_Cierre_Operativo]]="");"";SI([@[Fecha_Cierre_Operativo]]<=SI([@[Fecha_Nueva_Programada]]<>"";[@[Fecha_Nueva_Programada]];[@[Fecha_Programada_Fin]]);"SÍ";"NO")) | P66: =SI(O([@[Cumpli_Ingreso]]="";[@[Cumpli_Salida]]="");"";SI(Y([@[Cumpli_Ingreso]]="SÍ";[@[Cumpli_Salida]]="SÍ");"SÍ";"NO")) | Q66: =SI(O([@[Fecha_Programada_Fin]]="";[@[Fecha_Cierre_Operativo]]="");"";MAX(0;ENTERO([@[Fecha_Cierre_Operativo]])-ENTERO(SI([@[Fecha_Nueva_Programada]]<>"";[@[Fecha_Nueva_Programada]];[@[Fecha_Programada_Fin]]))) | U66: 13 | W66: =SI.ERROR(SI(O([@[Fecha_Programada_Inicio]]="";[@[Fecha_Programada_Fin]]="");"";SI(Y([@[Fecha_Programada_Fin]]>=[@[Fecha_Programada_Inicio]];SI([@[Fecha_Cierre_Operativo]]="";VERDADERO;[@[Fecha_Cierre_Operativo]]>=[@[Fecha_Inicio_Real]]);SI([@[Fecha_Cierre_Administrativo]]="";VERDADERO;Y([@[Fecha_Cierre_Operativo]]<>"";[@[Fecha_Cierre_Administrativo]]>=[@[Fecha_Cierre_Operativo]])));"OK";"REVISAR"));"REVISAR") | X66: =SI([@SBAN]="";"";BUSCARV([@SBAN];Cronograma_Maestro!$A:$M;6;FALSO))
A67: 1342 | B67: =SI([@SBAN]="";"";BUSCARV([@SBAN];Cronograma_Maestro!$A:$M;2;FALSO)) | C67: =SI([@SBAN]="";"";BUSCARV([@SBAN];Cronograma_Maestro!$A:$M;3;FALSO)) | D67: =SI([@SBAN]="";"";BUSCARV([@SBAN];Cronograma_Maestro!$A:$M;4;FALSO)) | E67: =SI([@SBAN]="";"";BUSCARV([@SBAN];Cronograma_Maestro!$A:$M;5;FALSO)) | F67: Juan Pablo Osorio Ramirez | G67: PMU COLSOF | H67: 46275 | I67: 46275 | L67: Programada | N67: =SI(O([@[Fecha_Programada_Inicio]]="";[@[Fecha_Inicio_Real]]="");"";SI([@[Fecha_Inicio_Real]]<=[@[Fecha_Programada_Inicio]];"SÍ";"NO")) | O67: =SI(O([@[Fecha_Programada_Fin]]="";[@[Fecha_Cierre_Operativo]]="");"";SI([@[Fecha_Cierre_Operativo]]<=SI([@[Fecha_Nueva_Programada]]<>"";[@[Fecha_Nueva_Programada]];[@[Fecha_Programada_Fin]]);"SÍ";"NO")) | P67: =SI(O([@[Cumpli_Ingreso]]="";[@[Cumpli_Salida]]="");"";SI(Y([@[Cumpli_Ingreso]]="SÍ";[@[Cumpli_Salida]]="SÍ");"SÍ";"NO")) | Q67: =SI(O([@[Fecha_Programada_Fin]]="";[@[Fecha_Cierre_Operativo]]="");"";MAX(0;ENTERO([@[Fecha_Cierre_Operativo]])-ENTERO(SI([@[Fecha_Nueva_Programada]]<>"";[@[Fecha_Nueva_Programada]];[@[Fecha_Programada_Fin]]))) | U67: 23 | W67: =SI.ERROR(SI(O([@[Fecha_Programada_Inicio]]="";[@[Fecha_Programada_Fin]]="");"";SI(Y([@[Fecha_Programada_Fin]]>=[@[Fecha_Programada_Inicio]];SI([@[Fecha_Cierre_Operativo]]="";VERDADERO;[@[Fecha_Cierre_Operativo]]>=[@[Fecha_Inicio_Real]]);SI([@[Fecha_Cierre_Administrativo]]="";VERDADERO;Y([@[Fecha_Cierre_Operativo]]<>"";[@[Fecha_Cierre_Administrativo]]>=[@[Fecha_Cierre_Operativo]])));"OK";"REVISAR"));"REVISAR") | X67: =SI([@SBAN]="";"";BUSCARV([@SBAN];Cronograma_Maestro!$A:$M;6;FALSO))
... A72: 1350 | B72: =SI([@SBAN]="";"";BUSCARV([@SBAN];Cronograma_Maestro!$A:$M;2;FALSO)) | C72: =SI([@SBAN]="";"";BUSCARV([@SBAN];Cronograma_Maestro!$A:$M;3;FALSO)) | D72: =SI([@SBAN]="";"";BUSCARV([@SBAN];Cronograma_Maestro!$A:$M;4;FALSO)) | E72: =SI([@SBAN]="";"";BUSCARV([@SBAN];Cronograma_Maestro!$A:$M;5;FALSO)) | F72: Juan Pablo Osorio Ramirez | G72: PMU COLSOF | H72: 46316 | I72: 46316 | L72: Programada | N72: =SI(O([@[Fecha_Programada_Inicio]]="";[@[Fecha_Inicio_Real]]="");"";SI([@[Fecha_Inicio_Real]]<=[@[Fecha_Programada_Inicio]];"SÍ";"NO")) | O72: =SI(O([@[Fecha_Programada_Fin]]="";[@[Fecha_Cierre_Operativo]]="");"";SI([@[Fecha_Cierre_Operativo]]<=SI([@[Fecha_Nueva_Programada]]<>"";[@[Fecha_Nueva_Programada]];[@[Fecha_Programada_Fin]]);"SÍ";"NO")) | P72: =SI(O([@[Cumpli_Ingreso]]="";[@[Cumpli_Salida]]="");"";SI(Y([@[Cumpli_Ingreso]]="SÍ";[@[Cumpli_Salida]]="SÍ");"SÍ";"NO")) | Q72: =SI(O([@[Fecha_Programada_Fin]]="";[@[Fecha_Cierre_Operativo]]="");"";MAX(0;ENTERO([@[Fecha_Cierre_Operativo]])-ENTERO(SI([@[Fecha_Nueva_Programada]]<>"";[@[Fecha_Nueva_Programada]];[@[Fecha_Programada_Fin]]))) | U72: 16 | W72: =SI.ERROR(SI(O([@[Fecha_Programada_Inicio]]="";[@[Fecha_Programada_Fin]]="");"";SI(Y([@[Fecha_Programada_Fin]]>=[@[Fecha_Programada_Inicio]];SI([@[Fecha_Cierre_Operativo]]="";VERDADERO;[@[Fecha_Cierre_Operativo]]>=[@[Fecha_Inicio_Real]]);SI([@[Fecha_Cierre_Administrativo]]="";VERDADERO;Y([@[Fecha_Cierre_Operativo]]<>"";[@[Fecha_Cierre_Administrativo]]>=[@[Fecha_Cierre_Operativo]])));"OK";"REVISAR"));"REVISAR") | X72: =SI([@SBAN]="";"";BUSCARV([@SBAN];Cronograma_Maestro!$A:$M;6;FALSO))
A73: 1351 | B73: =SI([@SBAN]="";"";BUSCARV([@SBAN];Cronograma_Maestro!$A:$M;2;FALSO)) | C73: =SI([@SBAN]="";"";BUSCARV([@SBAN];Cronograma_Maestro!$A:$M;3;FALSO)) | D73: =SI([@SBAN]="";"";BUSCARV([@SBAN];Cronograma_Maestro!$A:$M;4;FALSO)) | E73: =SI([@SBAN]="";"";BUSCARV([@SBAN];Cronograma_Maestro!$A:$M;5;FALSO)) | F73: Andrés Mariano Bustamante Castro | G73: PMU COLSOF | H73: 46266 | I73: 46268 | J73: 46266 | L73: En Proceso | N73: =SI(O([@[Fecha_Programada_Inicio]]="";[@[Fecha_Inicio_Real]]="");"";SI([@[Fecha_Inicio_Real]]<=[@[Fecha_Programada_Inicio]];"SÍ";"NO")) | O73: =SI(O([@[Fecha_Programada_Fin]]="";[@[Fecha_Cierre_Operativo]]="");"";SI([@[Fecha_Cierre_Operativo]]<=SI([@[Fecha_Nueva_Programada]]<>"";[@[Fecha_Nueva_Programada]];[@[Fecha_Programada_Fin]]);"SÍ";"NO")) | P73: =SI(O([@[Cumpli_Ingreso]]="";[@[Cumpli_Salida]]="");"";SI(Y([@[Cumpli_Ingreso]]="SÍ";[@[Cumpli_Salida]]="SÍ");"SÍ";"NO")) | Q73: =SI(O([@[Fecha_Programada_Fin]]="";[@[Fecha_Cierre_Operativo]]="");"";MAX(0;ENTERO([@[Fecha_Cierre_Operativo]])-ENTERO(SI([@[Fecha_Nueva_Programada]]<>"";[@[Fecha_Nueva_Programada]];[@[Fecha_Programada_Fin]]))) | U73: 31 | W73: =SI.ERROR(SI(O([@[Fecha_Programada_Inicio]]="";[@[Fecha_Programada_Fin]]="");"";SI(Y([@[Fecha_Programada_Fin]]>=[@[Fecha_Programada_Inicio]];SI([@[Fecha_Cierre_Operativo]]="";VERDADERO;[@[Fecha_Cierre_Operativo]]>=[@[Fecha_Inicio_Real]]);SI([@[Fecha_Cierre_Administrativo]]="";VERDADERO;Y([@[Fecha_Cierre_Operativo]]<>"";[@[Fecha_Cierre_Administrativo]]>=[@[Fecha_Cierre_Operativo]])));"OK";"REVISAR"));"REVISAR") | X73: =SI([@SBAN]="";"";BUSCARV([@SBAN];Cronograma_Maestro!$A:$M;6;FALSO))
A74: 1352 | B74: =SI([@SBAN]="";"";BUSCARV([@SBAN];Cronograma_Maestro!$A:$M;2;FALSO)) | C74: =SI([@SBAN]="";"";BUSCARV([@SBAN];Cronograma_Maestro!$A:$M;3;FALSO)) | D74: =SI([@SBAN]="";"";BUSCARV([@SBAN];Cronograma_Maestro!$A:$M;4;FALSO)) | E74: =SI([@SBAN]="";"";BUSCARV([@SBAN];Cronograma_Maestro!$A:$M;5;FALSO)) | F74: Ever Enrique Esquivel Movilla | G74: PMU COLSOF | H74: 46295 | I74: 46296 | L74: Programada | N74: =SI(O([@[Fecha_Programada_Inicio]]="";[@[Fecha_Inicio_Real]]="");"";SI([@[Fecha_Inicio_Real]]<=[@[Fecha_Programada_Inicio]];"SÍ";"NO")) | O74: =SI(O([@[Fecha_Programada_Fin]]="";[@[Fecha_Cierre_Operativo]]="");"";SI([@[Fecha_Cierre_Operativo]]<=SI([@[Fecha_Nueva_Programada]]<>"";[@[Fecha_Nueva_Programada]];[@[Fecha_Programada_Fin]]);"SÍ";"NO")) | P74: =SI(O([@[Cumpli_Ingreso]]="";[@[Cumpli_Salida]]="");"";SI(Y([@[Cumpli_Ingreso]]="SÍ";[@[Cumpli_Salida]]="SÍ");"SÍ";"NO")) | Q74: =SI(O([@[Fecha_Programada_Fin]]="";[@[Fecha_Cierre_Operativo]]="");"";MAX(0;ENTERO([@[Fecha_Cierre_Operativo]])-ENTERO(SI([@[Fecha_Nueva_Programada]]<>"";[@[Fecha_Nueva_Programada]];[@[Fecha_Programada_Fin]]))) | U74: 36 | W74: =SI.ERROR(SI(O([@[Fecha_Programada_Inicio]]="";[@[Fecha_Programada_Fin]]="");"";SI(Y([@[Fecha_Programada_Fin]]>=[@[Fecha_Programada_Inicio]];SI([@[Fecha_Cierre_Operativo]]="";VERDADERO;[@[Fecha_Cierre_Operativo]]>=[@[Fecha_Inicio_Real]]);SI([@[Fecha_Cierre_Administrativo]]="";VERDADERO;Y([@[Fecha_Cierre_Operativo]]<>"";[@[Fecha_Cierre_Administrativo]]>=[@[Fecha_Cierre_Operativo]])));"OK";"REVISAR"));"REVISAR") | X74: =SI([@SBAN]="";"";BUSCARV([@SBAN];Cronograma_Maestro!$A:$M;6;FALSO))
A75: 1353 | B75: =SI([@SBAN]="";"";BUSCARV([@SBAN];Cronograma_Maestro!$A:$M;2;FALSO)) | C75: =SI([@SBAN]="";"";BUSCARV([@SBAN];Cronograma_Maestro!$A:$M;3;FALSO)) | D75: =SI([@SBAN]="";"";BUSCARV([@SBAN];Cronograma_Maestro!$A:$M;4;FALSO)) | E75: =SI([@SBAN]="";"";BUSCARV([@SBAN];Cronograma_Maestro!$A:$M;5;FALSO)) | F75: Juan Pablo Osorio Ramirez | G75: PMU COLSOF | H75: 46266 | I75: 46266 | J75: 46266 | K75: 46266 | L75: Finalizada | N75: =SI(O([@[Fecha_Programada_Inicio]]="";[@[Fecha_Inicio_Real]]="");"";SI([@[Fecha_Inicio_Real]]<=[@[Fecha_Programada_Inicio]];"SÍ";"NO")) | O75: =SI(O([@[Fecha_Programada_Fin]]="";[@[Fecha_Cierre_Operativo]]="");"";SI([@[Fecha_Cierre_Operativo]]<=SI([@[Fecha_Nueva_Programada]]<>"";[@[Fecha_Nueva_Programada]];[@[Fecha_Programada_Fin]]);"SÍ";"NO")) | P75: =SI(O([@[Cumpli_Ingreso]]="";[@[Cumpli_Salida]]="");"";SI(Y([@[Cumpli_Ingreso]]="SÍ";[@[Cumpli_Salida]]="SÍ");"SÍ";"NO")) | Q75: =SI(O([@[Fecha_Programada_Fin]]="";[@[Fecha_Cierre_Operativo]]="");"";MAX(0;ENTERO([@[Fecha_Cierre_Operativo]])-ENTERO(SI([@[Fecha_Nueva_Programada]]<>"";[@[Fecha_Nueva_Programada]];[@[Fecha_Programada_Fin]]))) | R75: N/A - A Tiempo | S75: Firmada | U75: 13 | V75: El directo del Sban se encentra en vacaiones, firma en su nombre el encargdo del cargo durante su ausencia Zayda Cabanzo | W75: =SI.ERROR(SI(O([@[Fecha_Programada_Inicio]]="";[@[Fecha_Programada_Fin]]="");"";SI(Y([@[Fecha_Programada_Fin]]>=[@[Fecha_Programada_Inicio]];SI([@[Fecha_Cierre_Operativo]]="";VERDADERO;[@[Fecha_Cierre_Operativo]]>=[@[Fecha_Inicio_Real]]);SI([@[Fecha_Cierre_Administrativo]]="";VERDADERO;Y([@[Fecha_Cierre_Operativo]]<>"";[@[Fecha_Cierre_Administrativo]]>=[@[Fecha_Cierre_Operativo]])));"OK";"REVISAR"));"REVISAR") | X75: =SI([@SBAN]="";"";BUSCARV([@SBAN];Cronograma_Maestro!$A:$M;6;FALSO))
A76: 1354 | B76: =SI([@SBAN]="";"";BUSCARV([@SBAN];Cronograma_Maestro!$A:$M;2;FALSO)) | C76: =SI([@SBAN]="";"";BUSCARV([@SBAN];Cronograma_Maestro!$A:$M;3;FALSO)) | D76: =SI([@SBAN]="";"";BUSCARV([@SBAN];Cronograma_Maestro!$A:$M;4;FALSO)) | E76: =SI([@SBAN]="";"";BUSCARV([@SBAN];Cronograma_Maestro!$A:$M;5;FALSO)) | F76: Juan Pablo Osorio Ramirez | G76: PMU COLSOF | H76: 46273 | I76: 46273 | L76: Programada | N76: =SI(O([@[Fecha_Programada_Inicio]]="";[@[Fecha_Inicio_Real]]="");"";SI([@[Fecha_Inicio_Real]]<=[@[Fecha_Programada_Inicio]];"SÍ";"NO")) | O76: =SI(O([@[Fecha_Programada_Fin]]="";[@[Fecha_Cierre_Operativo]]="");"";SI([@[Fecha_Cierre_Operativo]]<=SI([@[Fecha_Nueva_Programada]]<>"";[@[Fecha_Nueva_Programada]];[@[Fecha_Programada_Fin]]);"SÍ";"NO")) | P76: =SI(O([@[Cumpli_Ingreso]]="";[@[Cumpli_Salida]]="");"";SI(Y([@[Cumpli_Ingreso]]="SÍ";[@[Cumpli_Salida]]="SÍ");"SÍ";"NO")) | Q76: =SI(O([@[Fecha_Programada_Fin]]="";[@[Fecha_Cierre_Operativo]]="");"";MAX(0;ENTERO([@[Fecha_Cierre_Operativo]])-ENTERO(SI([@[Fecha_Nueva_Programada]]<>"";[@[Fecha_Nueva_Programada]];[@[Fecha_Programada_Fin]]))) | U76: 17 | W76: =SI.ERROR(SI(O([@[Fecha_Programada_Inicio]]="";[@[Fecha_Programada_Fin]]="");"";SI(Y([@[Fecha_Programada_Fin]]>=[@[Fecha_Programada_Inicio]];SI([@[Fecha_Cierre_Operativo]]="";VERDADERO;[@[Fecha_Cierre_Operativo]]>=[@[Fecha_Inicio_Real]]);SI([@[Fecha_Cierre_Administrativo]]="";VERDADERO;Y([@[Fecha_Cierre_Operativo]]<>"";[@[Fecha_Cierre_Administrativo]]>=[@[Fecha_Cierre_Operativo]])));"OK";"REVISAR"));"REVISAR") | X76: =SI([@SBAN]="";"";BUSCARV([@SBAN];Cronograma_Maestro!$A:$M;6;FALSO))
A77: 1355 | B77: =SI([@SBAN]="";"";BUSCARV([@SBAN];Cronograma_Maestro!$A:$M;2;FALSO)) | C77: =SI([@SBAN]="";"";BUSCARV([@SBAN];Cronograma_Maestro!$A:$M;3;FALSO)) | D77: =SI([@SBAN]="";"";BUSCARV([@SBAN];Cronograma_Maestro!$A:$M;4;FALSO)) | E77: =SI([@SBAN]="";"";BUSCARV([@SBAN];Cronograma_Maestro!$A:$M;5;FALSO)) | F77: Andrés Mariano Bustamante Castro | G77: PMU COLSOF | H77: 46308 | I77: 46308 | L77: Programada | N77: =SI(O([@[Fecha_Programada_Inicio]]="";[@[Fecha_Inicio_Real]]="");"";SI([@[Fecha_Inicio_Real]]<=[@[Fecha_Programada_Inicio]];"SÍ";"NO")) | O77: =SI(O([@[Fecha_Programada_Fin]]="";[@[Fecha_Cierre_Operativo]]="");"";SI([@[Fecha_Cierre_Operativo]]<=SI([@[Fecha_Nueva_Programada]]<>"";[@[Fecha_Nueva_Programada]];[@[Fecha_Programada_Fin]]);"SÍ";"NO")) | P77: =SI(O([@[Cumpli_Ingreso]]="";[@[Cumpli_Salida]]="");"";SI(Y([@[Cumpli_Ingreso]]="SÍ";[@[Cumpli_Salida]]="SÍ");"SÍ";"NO")) | Q77: =SI(O([@[Fecha_Programada_Fin]]="";[@[Fecha_Cierre_Operativo]]="");"";MAX(0;ENTERO([@[Fecha_Cierre_Operativo]])-ENTERO(SI([@[Fecha_Nueva_Programada]]<>"";[@[Fecha_Nueva_Programada]];[@[Fecha_Programada_Fin]]))) | U77: 19 | W77: =SI.ERROR(SI(O([@[Fecha_Programada_Inicio]]="";[@[Fecha_Programada_Fin]]="");"";SI(Y([@[Fecha_Programada_Fin]]>=[@[Fecha_Programada_Inicio]];SI([@[Fecha_Cierre_Operativo]]="";VERDADERO;[@[Fecha_Cierre_Operativo]]>=[@[Fecha_Inicio_Real]]);SI([@[Fecha_Cierre_Administrativo]]="";VERDADERO;Y([@[Fecha_Cierre_Operativo]]<>"";[@[Fecha_Cierre_Administrativo]]>=[@[Fecha_Cierre_Operativo]])));"OK";"REVISAR"));"REVISAR") | X77: =SI([@SBAN]="";"";BUSCARV([@SBAN];Cronograma_Maestro!$A:$M;6;FALSO))
A78: 1356 | B78: =SI([@SBAN]="";"";BUSCARV([@SBAN];Cronograma_Maestro!$A:$M;2;FALSO)) | C78: =SI([@SBAN]="";"";BUSCARV([@SBAN];Cronograma_Maestro!$A:$M;3;FALSO)) | D78: =SI([@SBAN]="";"";BUSCARV([@SBAN];Cronograma_Maestro!$A:$M;4;FALSO)) | E78: =SI([@SBAN]="";"";BUSCARV([@SBAN];Cronograma_Maestro!$A:$M;5;FALSO)) | F78: Ever Enrique Esquivel Movilla | G78: PMU COLSOF | H78: 46297 | I78: 46297 | L78: Programada | N78: =SI(O([@[Fecha_Programada_Inicio]]="";[@[Fecha_Inicio_Real]]="");"";SI([@[Fecha_Inicio_Real]]<=[@[Fecha_Programada_Inicio]];"SÍ";"NO")) | O78: =SI(O([@[Fecha_Programada_Fin]]="";[@[Fecha_Cierre_Operativo]]="");"";SI([@[Fecha_Cierre_Operativo]]<=SI([@[Fecha_Nueva_Programada]]<>"";[@[Fecha_Nueva_Programada]];[@[Fecha_Programada_Fin]]);"SÍ";"NO")) | P78: =SI(O([@[Cumpli_Ingreso]]="";[@[Cumpli_Salida]]="");"";SI(Y([@[Cumpli_Ingreso]]="SÍ";[@[Cumpli_Salida]]="SÍ");"SÍ";"NO")) | Q78: =SI(O([@[Fecha_Programada_Fin]]="";[@[Fecha_Cierre_Operativo]]="");"";MAX(0;ENTERO([@[Fecha_Cierre_Operativo]])-ENTERO(SI([@[Fecha_Nueva_Programada]]<>"";[@[Fecha_Nueva_Programada]];[@[Fecha_Programada_Fin]]))) | U78: 13 | W78: =SI.ERROR(SI(O([@[Fecha_Programada_Inicio]]="";[@[Fecha_Programada_Fin]]="");"";SI(Y([@[Fecha_Programada_Fin]]>=[@[Fecha_Programada_Inicio]];SI([@[Fecha_Cierre_Operativo]]="";VERDADERO;[@[Fecha_Cierre_Operativo]]>=[@[Fecha_Inicio_Real]]);SI([@[Fecha_Cierre_Administrativo]]="";VERDADERO;Y([@[Fecha_Cierre_Operativo]]<>"";[@[Fecha_Cierre_Administrativo]]>=[@[Fecha_Cierre_Operativo]])));"OK";"REVISAR"));"REVISAR") | X78: =SI([@SBAN]="";"";BUSCARV([@SBAN];Cronograma_Maestro!$A:$M;6;FALSO))
A79: 1357 | B79: =SI([@SBAN]="";"";BUSCARV([@SBAN];Cronograma_Maestro!$A:$M;2;FALSO)) | C79: =SI([@SBAN]="";"";BUSCARV([@SBAN];Cronograma_Maestro!$A:$M;3;FALSO)) | D79: =SI([@SBAN]="";"";BUSCARV([@SBAN];Cronograma_Maestro!$A:$M;4;FALSO)) | E79: =SI([@SBAN]="";"";BUSCARV([@SBAN];Cronograma_Maestro!$A:$M;5;FALSO)) | F79: Juan Pablo Osorio Ramirez | G79: PMU COLSOF | H79: 46280 | I79: 46280 | L79: Programada | N79: =SI(O([@[Fecha_Programada_Inicio]]="";[@[Fecha_Inicio_Real]]="");"";SI([@[Fecha_Inicio_Real]]<=[@[Fecha_Programada_Inicio]];"SÍ";"NO")) | O79: =SI(O([@[Fecha_Programada_Fin]]="";[@[Fecha_Cierre_Operativo]]="");"";SI([@[Fecha_Cierre_Operativo]]<=SI([@[Fecha_Nueva_Programada]]<>"";[@[Fecha_Nueva_Programada]];[@[Fecha_Programada_Fin]]);"SÍ";"NO")) | P79: =SI(O([@[Cumpli_Ingreso]]="";[@[Cumpli_Salida]]="");"";SI(Y([@[Cumpli_Ingreso]]="SÍ";[@[Cumpli_Salida]]="SÍ");"SÍ";"NO")) | Q79: =SI(O([@[Fecha_Programada_Fin]]="";[@[Fecha_Cierre_Operativo]]="");"";MAX(0;ENTERO([@[Fecha_Cierre_Operativo]])-ENTERO(SI([@[Fecha_Nueva_Programada]]<>"";[@[Fecha_Nueva_Programada]];[@[Fecha_Programada_Fin]]))) | U79: 13 | W79: =SI.ERROR(SI(O([@[Fecha_Programada_Inicio]]="";[@[Fecha_Programada_Fin]]="");"";SI(Y([@[Fecha_Programada_Fin]]>=[@[Fecha_Programada_Inicio]];SI([@[Fecha_Cierre_Operativo]]="";VERDADERO;[@[Fecha_Cierre_Operativo]]>=[@[Fecha_Inicio_Real]]);SI([@[Fecha_Cierre_Administrativo]]="";VERDADERO;Y([@[Fecha_Cierre_Operativo]]<>"";[@[Fecha_Cierre_Administrativo]]>=[@[Fecha_Cierre_Operativo]])));"OK";"REVISAR"));"REVISAR") | X79: =SI([@SBAN]="";"";BUSCARV([@SBAN];Cronograma_Maestro!$A:$M;6;FALSO))
