Workbook
Name REGIONES: Listas_Validacion!$A$3:$A$12
Name ESTADOS: Listas_Validacion!$C$3:$C$8
Name CAUSALES: Listas_Validacion!$E$3:$E$9
Name ESTATUS_ACTA: Listas_Validacion!$G$3:$G$5
Name SI_NO: Listas_Validacion!$I$3:$I$4

Sheet Instructivo_Tecnico
A1: INSTRUCTIVO TÉCNICO — BITÁCORA DIARIA DE MANTENIMIENTOS Y AUDITORÍA DE CALIDAD
A3: CÓMO USAR (resumen)
A4: 1. Al programar una sede: diligencie ID_Orden, Nombre_Oficina, Municipio, Departamento, Region, Técnicos y las fechas programadas (A-I) y el Estado (L).
A5: 2. Al iniciar la intervención en campo: registre Fecha_Inicio_Real (J).
A6: 3. Al terminar en campo: registre Fecha_Cierre_Operativo (K) y ponga Estado = Finalizada (L).
A7: 4. Si no se pudo ejecutar: Estado = Reprogramada (L), Fecha_Nueva_Programada (M) y Causal_Desviacion (R).
A8: 5. Calidad: al validar evidencias y firmar, registre Estatus_Acta (S), Fecha_Cierre_Administrativo (T) y Estado = Sede_Cerrada (L).
A9: 6. NO escriba en las columnas N, O, P, Q: son fórmulas automáticas.
A10: 7. El Dashboard_KPIs se actualiza solo. Revise Parámetros (Mes, Año, Metas) en esa pestaña.
A12: ESPECIFICACIÓN DE CAMPOS — BITACORA_DIARIA
A13: Col | B13: Campo | C13: Tipo de Dato | D13: ¿Qué información poner? | E13: Regla de negocio / Validación | F13: ¿Por qué se registra? | G13: ¿Para qué sirve? (KPI/Impacto)
A14: A | B14: ID_Orden | C14: Texto | D14: Código único de la sede (SBAN), ej. 1321 | E14: Obligatorio, no repetir | F14: Identifica la orden de mantenimiento | G14: Conteo total de mantenimientos (KPI Total)
A15: B | B15: Nombre_Oficina | C15: Texto | D15: Nombre de la oficina, ej. CAUCASIA | E15: Obligatorio | F15: Ubica geográficamente la intervención | G15: Filtros y conteos por oficina
A16: C | B16: Municipio | C16: Texto | D16: Municipio donde está la sede | E16: Opcional | F16: Contexto geográfico | G16: Desgloses geográficos
A17: D | B17: Departamento | C17: Texto | D17: Departamento de la sede | E17: Opcional; coherente con Region | F17: Contexto geográfico | G17: Validación cruzada con Region
A18: E | B18: Region | C18: Desplegable | D18: Jefatura operativa: ANTIOQUIA, ORIENTE, COSTA, SUR, OCCIDENTE, SANTANDERES, CAFETERA, BOGOTA, DIRECCION GENERAL, COA | E18: Obligatorio (lista) | F18: Agrupa la gestión por jefatura | G18: Tabla 'Mantenimientos por Región'
A19: F | B19: Tecnico_Operativo | C19: Texto | D19: Técnico(s) que interviene(n) en campo | E19: Obligatorio | F19: Trazabilidad de la ejecución | G19: KPI por técnico (cumplimiento y desviación)
A20: G | B20: Tecnico_Calidad | C20: Texto | D20: Responsable de calidad que audita | E20: Obligatorio | F20: Trazabilidad de la auditoría | G20: Auditoría de calidad
A21: H | B21: Fecha_Programada_Inicio | C21: Fecha dd/mm/aaaa (DÍA/MES/AÑO) | D21: Fecha en que estaba programado iniciar | E21: Obligatoria; fecha válida | F21: Define el cronograma comprometido | G21: Cumpli_Ingreso
A22: I | B22: Fecha_Programada_Fin | C22: Fecha dd/mm/aaaa (DÍA/MES/AÑO) | D22: Fecha comprometida de término | E22: Obligatoria; ≥ H | F22: Define la meta de cierre | G22: Cumpli_Salida y desviación en días
A23: J | B23: Fecha_Inicio_Real | C23: Fecha dd/mm/aaaa (DÍA/MES/AÑO) | D23: Fecha en que realmente se inició | E23: Se diligencia al llegar | F23: Mide el desfase de arranque | G23: Cumpli_Ingreso
A24: K | B24: Fecha_Cierre_Operativo | C24: Fecha dd/mm/aaaa (DÍA/MES/AÑO) | D24: Fecha en que el técnico terminó en campo | E24: Obligatoria si Estado = Finalizada o Sede_Cerrada | F24: Es el cierre operativo | G24: Cumpli_Salida, desviación en días, avance diario y acumulado del mes
... A35: V | B35: Observaciones_Calidad | C35: Texto | D35: Novedades, hallazgos, soportes | E35: Libre | F35: Contexto de la auditoría | G35: Análisis cualitativo
A37: REGLAS DE NEGOCIO Y DEFINICIÓN DE KPIs
A38: Cierre Operativo = Estado Finalizada con Fecha_Cierre_Operativo registrada (el técnico terminó en campo).
A39: Cierre Administrativo = Estado Sede_Cerrada con Estatus_Acta = Firmada y Fecha_Cierre_Administrativo (calidad validó y firmó).
A40: Ejecutadas = Finalizada + Sede_Cerrada. Pendientes = Programada + En Proceso + Reprogramada.
A41: Evaluables = registros con Cumpli_Cronograma SÍ o NO + Reprogramadas (base de cumplimiento y desviación).
A42: Desviación (días) = Fecha_Cierre_Operativo − fecha comprometida vigente (Fecha_Nueva_Programada si existe, si no Fecha_Programada_Fin); se toma solo si es > 0.
A43: Avance del plan = Ejecutadas / Total. Tasa de Cumplimiento = Cumplen (SÍ) / Evaluables.
A44: % Desviación = Desvían (NO + Reprogramadas) / Evaluables. Desviación promedio = promedio de días en registros NO.
A45: Acumulado del mes / Promedio diario / Máximo en el día: se calculan con Fecha_Cierre_Operativo del mes indicado en Parámetros.
A46: Equipos impactados = suma de Cantidad_Equipos de las sedes Finalizada y Sede_Cerrada.

Sheet Listas_Validacion
A1: LISTAS PARA VALIDACIÓN DE DATOS (no editar la posición de las listas)
A2: REGIONES | C2: ESTADOS | E2: CAUSALES | G2: ESTATUS_ACTA | I2: SI_NO | K2: Departamento | L2: Region
A3: ANTIOQUIA | C3: Programada | E3: N/A - A Tiempo | G3: Pendiente Firma | I3: SÍ | K3: Amazonas | L3: BOGOTA
A4: ORIENTE | C4: En Proceso | E4: Repuesto Faltante | G4: Firmada | I4: NO | K4: Antioquia | L4: ANTIOQUIA
A5: COSTA | C5: Finalizada | E5: Director Oficina No Disponible | K5: Antioquia | L5: COSTA
A6: SUR | C6: Reprogramada | E6: Clima | K6: Antioquia | L6: SANTANDERES
A7: OCCIDENTE | C7: Sede_Cerrada | E7: Falla Técnica | K7: Arauca | L7: BOGOTA
A8: SANTANDERES | C8: Cancelada | E8: Reprogramación Cliente | K8: Archipiélago de San Andrés, Providencia y Santa Catalina | L8: COSTA
A9: CAFETERA | E9: Logística/Acceso | K9: Atlántico | L9: COSTA
A10: BOGOTA | K10: Bogotá D.C | L10: BOGOTA
A11: DIRECCION GENERAL | K11: Bolívar | L11: COSTA
A12: COA | K12: Bolívar | L12: SANTANDERES
K13: Boyacá | L13: BOGOTA
K14: Boyacá | L14: ORIENTE
K15: CAUCA | L15: OCCIDENTE
K16: Caldas | L16: CAFETERA
K17: Caquetá | L17: SUR
K18: Casanare | L18: BOGOTA
K19: Casanare | L19: ORIENTE
K20: Cauca | L20: OCCIDENTE
K21: Cauca | L21: SUR
K22: Cesar | L22: COSTA
K23: Cesar | L23: SANTANDERES
K24: Chocó | L24: ANTIOQUIA
... K51: Vichada | L51: BOGOTA

Sheet Bitacora_Diaria
A1: ID_Orden | B1: Nombre_Oficina | C1: Municipio | D1: Departamento | E1: Region | F1: Tecnico_Operativo | G1: Tecnico_Calidad | H1: Fecha_Programada_Inicio | I1: Fecha_Programada_Fin | J1: Fecha_Inicio_Real | K1: Fecha_Cierre_Operativo | L1: Estado_Mantenimiento | M1: Fecha_Nueva_Programada | N1: Cumpli_Ingreso | O1: Cumpli_Salida | P1: Cumpli_Cronograma | Q1: Dias_Desviacion | R1: Causal_Desviacion | S1: Estatus_Acta | T1: Fecha_Cierre_Administrativo | U1: Cantidad_Equipos | V1: Observaciones_Calidad
A2: 1321 | B2: CAUCASIA | C2: Caucasia | D2: Antioquia | E2: ANTIOQUIA | F2: Ever Enrique Esquivel Movilla | G2: 8 | H2: 46266 | I2: 46267 | J2: 46266 | L2: En Proceso | N2: =SI(O(H2="";J2="");"";SI(J2<=H2;"SÍ";"NO")) | O2: =SI(O(I2="";K2="");"";SI(K2<=SI(M2<>"";M2;I2);"SÍ";"NO")) | P2: =SI(O(N2="";O2="");"";SI(Y(N2="SÍ";O2="SÍ");"SÍ";"NO")) | Q2: =SI(O(I2="";K2="");"";MAX(0;ENTERO(K2)-ENTERO(SI(M2<>"";M2;I2)))) | U2: 39 | V2: No firma el director debido en vacaiones, firma el encergado de la sede
A3: 1351 | B3: BELLO | C3: Bello | D3: Antioquia | E3: ANTIOQUIA | F3: Andrés Mariano Bustamante Castro | G3: 5 | H3: 46266 | I3: 46268 | J3: 46266 | L3: En Proceso | N3: =SI(O(H3="";J3="");"";SI(J3<=H3;"SÍ";"NO")) | O3: =SI(O(I3="";K3="");"";SI(K3<=SI(M3<>"";M3;I3);"SÍ";"NO")) | P3: =SI(O(N3="";O3="");"";SI(Y(N3="SÍ";O3="SÍ");"SÍ";"NO")) | Q3: =SI(O(I3="";K3="");"";MAX(0;ENTERO(K3)-ENTERO(SI(M3<>"";M3;I3)))) | U3: 36
A4: 1353 | B4: EBEJICO | C4: Ebéjico | D4: Antioquia | E4: ANTIOQUIA | F4: Juan Pablo Osorio Ramirez | G4: 1 | H4: 46266 | I4: 46266 | J4: 46266 | K4: 46266 | L4: Finalizada | N4: =SI(O(H4="";J4="");"";SI(J4<=H4;"SÍ";"NO")) | O4: =SI(O(I4="";K4="");"";SI(K4<=SI(M4<>"";M4;I4);"SÍ";"NO")) | P4: =SI(O(N4="";O4="");"";SI(Y(N4="SÍ";O4="SÍ");"SÍ";"NO")) | Q4: =SI(O(I4="";K4="");"";MAX(0;ENTERO(K4)-ENTERO(SI(M4<>"";M4;I4)))) | R4: N/A - A Tiempo | S4: Firmada | U4: 15 | V4: El directo del Sban se encentra en vacaiones, firma en su nombre el encargdo del cargo durante su ausencia Zayda Cabanzo
A5: 1444 | B5: NECHI | C5: Nechí | D5: Antioquia | E5: ANTIOQUIA | F5: Ever Enrique Esquivel Movilla | G5: 3 | H5: 46266 | I5: 46266 | J5: 46266 | K5: 46266 | L5: Finalizada | N5: =SI(O(H5="";J5="");"";SI(J5<=H5;"SÍ";"NO")) | O5: =SI(O(I5="";K5="");"";SI(K5<=SI(M5<>"";M5;I5);"SÍ";"NO")) | P5: =SI(O(N5="";O5="");"";SI(Y(N5="SÍ";O5="SÍ");"SÍ";"NO")) | Q5: =SI(O(I5="";K5="");"";MAX(0;ENTERO(K5)-ENTERO(SI(M5<>"";M5;I5)))) | R5: N/A - A Tiempo | S5: Pendiente Firma | U5: 18
A6: 1506 | B6: BOAVITA | C6: Boavita | D6: Boyacá | E6: ORIENTE | F6: Luz Nélida Barragán Toro | G6: 2 | H6: 46266 | I6: 46267 | J6: 46266 | L6: En Proceso | N6: =SI(O(H6="";J6="");"";SI(J6<=H6;"SÍ";"NO")) | O6: =SI(O(I6="";K6="");"";SI(K6<=SI(M6<>"";M6;I6);"SÍ";"NO")) | P6: =SI(O(N6="";O6="");"";SI(Y(N6="SÍ";O6="SÍ");"SÍ";"NO")) | Q6: =SI(O(I6="";K6="");"";MAX(0;ENTERO(K6)-ENTERO(SI(M6<>"";M6;I6)))) | U6: 15
A7: 1544 | B7: LA UVITA | C7: La Uvita | D7: Boyacá | E7: ORIENTE | F7: Andrés Felipe Díaz Noy | G7: 1 | H7: 46266 | I7: 46267 | J7: 46266 | L7: En Proceso | N7: =SI(O(H7="";J7="");"";SI(J7<=H7;"SÍ";"NO")) | O7: =SI(O(I7="";K7="");"";SI(K7<=SI(M7<>"";M7;I7);"SÍ";"NO")) | P7: =SI(O(N7="";O7="");"";SI(Y(N7="SÍ";O7="SÍ");"SÍ";"NO")) | Q7: =SI(O(I7="";K7="");"";MAX(0;ENTERO(K7)-ENTERO(SI(M7<>"";M7;I7)))) | U7: 13
A8: 1582 | B8: SUSACON | C8: Susacón | D8: Boyacá | E8: ORIENTE | F8: Andrés Felipe Carvajal Pire | G8: 1 | H8: 46266 | I8: 46267 | J8: 46266 | L8: En Proceso | N8: =SI(O(H8="";J8="");"";SI(J8<=H8;"SÍ";"NO")) | O8: =SI(O(I8="";K8="");"";SI(K8<=SI(M8<>"";M8;I8);"SÍ";"NO")) | P8: =SI(O(N8="";O8="");"";SI(Y(N8="SÍ";O8="SÍ");"SÍ";"NO")) | Q8: =SI(O(I8="";K8="");"";MAX(0;ENTERO(K8)-ENTERO(SI(M8<>"";M8;I8)))) | U8: 13
A9: 1586 | B9: TIPACOQUE | C9: Tipacoque | D9: Boyacá | E9: ORIENTE | F9: Mauricio Andrés Rivera Páez | G9: 1 | H9: 46266 | I9: 46267 | J9: 46266 | L9: En Proceso | N9: =SI(O(H9="";J9="");"";SI(J9<=H9;"SÍ";"NO")) | O9: =SI(O(I9="";K9="");"";SI(K9<=SI(M9<>"";M9;I9);"SÍ";"NO")) | P9: =SI(O(N9="";O9="");"";SI(Y(N9="SÍ";O9="SÍ");"SÍ";"NO")) | Q9: =SI(O(I9="";K9="");"";MAX(0;ENTERO(K9)-ENTERO(SI(M9<>"";M9;I9)))) | U9: 13
A10: 2712 | B10: BUENAVISTA | C10: Buenavista | D10: Córdoba | E10: ANTIOQUIA | F10: Jorge Felipe Munive Medina | G10: 2 | H10: 46266 | I10: 46266 | J10: 46266 | K10: 46266 | L10: Finalizada | N10: =SI(O(H10="";J10="");"";SI(J10<=H10;"SÍ";"NO")) | O10: =SI(O(I10="";K10="");"";SI(K10<=SI(M10<>"";M10;I10);"SÍ";"NO")) | P10: =SI(O(N10="";O10="");"";SI(Y(N10="SÍ";O10="SÍ");"SÍ";"NO")) | Q10: =SI(O(I10="";K10="");"";MAX(0;ENTERO(K10)-ENTERO(SI(M10<>"";M10;I10)))) | R10: N/A - A Tiempo | S10: Pendiente Firma | U10: 15
A11: 2777 | B11: SAN ANTERO | C11: San Antero | D11: Córdoba | E11: COSTA | F11: Dimar Jose Morelo Cardona | G11: 3 | H11: 46266 | I11: 46266 | J11: 46266 | K11: 46266 | L11: Finalizada | N11: =SI(O(H11="";J11="");"";SI(J11<=H11;"SÍ";"NO")) | O11: =SI(O(I11="";K11="");"";SI(K11<=SI(M11<>"";M11;I11);"SÍ";"NO")) | P11: =SI(O(N11="";O11="");"";SI(Y(N11="SÍ";O11="SÍ");"SÍ";"NO")) | Q11: =SI(O(I11="";K11="");"";MAX(0;ENTERO(K11)-ENTERO(SI(M11<>"";M11;I11)))) | R11: N/A - A Tiempo | S11: Pendiente Firma | U11: 17
A12: 3935 | B12: IQUIRA | C12: Iquira | D12: Huila | E12: SUR | F12: ERIKA VARGAS | G12: 2 | H12: 46266 | I12: 46266 | J12: 46266 | K12: 46266 | L12: Finalizada | N12: =SI(O(H12="";J12="");"";SI(J12<=H12;"SÍ";"NO")) | O12: =SI(O(I12="";K12="");"";SI(K12<=SI(M12<>"";M12;I12);"SÍ";"NO")) | P12: =SI(O(N12="";O12="");"";SI(Y(N12="SÍ";O12="SÍ");"SÍ";"NO")) | Q12: =SI(O(I12="";K12="");"";MAX(0;ENTERO(K12)-ENTERO(SI(M12<>"";M12;I12)))) | R12: N/A - A Tiempo | S12: Pendiente Firma | U12: 18
A13: 4540 | B13: SAN CARLOS DE GUAROA | C13: San Carlos De Guaroa | D13: Meta | E13: BOGOTA | F13: Andres Felipe Balbin | G13: 3 | H13: 46266 | I13: 46266 | J13: 46266 | K13: 46266 | L13: Finalizada | N13: =SI(O(H13="";J13="");"";SI(J13<=H13;"SÍ";"NO")) | O13: =SI(O(I13="";K13="");"";SI(K13<=SI(M13<>"";M13;I13);"SÍ";"NO")) | P13: =SI(O(N13="";O13="");"";SI(Y(N13="SÍ";O13="SÍ");"SÍ";"NO")) | Q13: =SI(O(I13="";K13="");"";MAX(0;ENTERO(K13)-ENTERO(SI(M13<>"";M13;I13)))) | R13: N/A - A Tiempo | S13: Pendiente Firma | U13: 17
A14: 5170 | B14: TIBU | C14: Tibú | D14: Norte de Santander | E14: SANTANDERES | F14: Juan Alfonso Cuberos Buendia-Ali Kassem Issa Sierra | G14: 6 | H14: 46266 | I14: 46269 | J14: 46266 | L14: En Proceso | N14: =SI(O(H14="";J14="");"";SI(J14<=H14;"SÍ";"NO")) | O14: =SI(O(I14="";K14="");"";SI(K14<=SI(M14<>"";M14;I14);"SÍ";"NO")) | P14: =SI(O(N14="";O14="");"";SI(Y(N14="SÍ";O14="SÍ");"SÍ";"NO")) | Q14: =SI(O(I14="";K14="");"";MAX(0;ENTERO(K14)-ENTERO(SI(M14<>"";M14;I14)))) | U14: 44
A15: 6607 | B15: CAJAMARCA | C15: Cajamarca | D15: Tolima | E15: SUR | F15: Fernando Valencia- Bernardo Arango | G15: 3 | H15: 46266 | I15: 46267 | J15: 46266 | L15: En Proceso | N15: =SI(O(H15="";J15="");"";SI(J15<=H15;"SÍ";"NO")) | O15: =SI(O(I15="";K15="");"";SI(K15<=SI(M15<>"";M15;I15);"SÍ";"NO")) | P15: =SI(O(N15="";O15="");"";SI(Y(N15="SÍ";O15="SÍ");"SÍ";"NO")) | Q15: =SI(O(I15="";K15="");"";MAX(0;ENTERO(K15)-ENTERO(SI(M15<>"";M15;I15)))) | U15: 22
A16: 6627 | B16: ANZOATEGUI | C16: Anzoátegui | D16: Tolima | E16: SUR | F16: Yeisson Castaño | G16: 1 | H16: 46266 | I16: 46266 | J16: 46266 | K16: 46266 | L16: Finalizada | N16: =SI(O(H16="";J16="");"";SI(J16<=H16;"SÍ";"NO")) | O16: =SI(O(I16="";K16="");"";SI(K16<=SI(M16<>"";M16;I16);"SÍ";"NO")) | P16: =SI(O(N16="";O16="");"";SI(Y(N16="SÍ";O16="SÍ");"SÍ";"NO")) | Q16: =SI(O(I16="";K16="");"";MAX(0;ENTERO(K16)-ENTERO(SI(M16<>"";M16;I16)))) | R16: N/A - A Tiempo | S16: Pendiente Firma | U16: 16
A17: 6640 | B17: CARMEN DE APICALA | C17: Carmen De Apicalá | D17: Tolima | E17: SUR | F17: Johan Molano | G17: 2 | H17: 46266 | I17: 46266 | L17: Reprogramada | M17: 46241 | N17: =SI(O(H17="";J17="");"";SI(J17<=H17;"SÍ";"NO")) | O17: =SI(O(I17="";K17="");"";SI(K17<=SI(M17<>"";M17;I17);"SÍ";"NO")) | P17: =SI(O(N17="";O17="");"";SI(Y(N17="SÍ";O17="SÍ");"SÍ";"NO")) | Q17: =SI(O(I17="";K17="");"";MAX(0;ENTERO(K17)-ENTERO(SI(M17<>"";M17;I17)))) | R17: Logística/Acceso | U17: 20 | V17: Derrumbe en la zona que impide el acceso
A18: 6642 | B18: PLANADAS | C18: Planadas | D18: Tolima | E18: SUR | F18: Johan Cardenas | G18: 3 | H18: 46266 | I18: 46267 | J18: 46266 | L18: En Proceso | N18: =SI(O(H18="";J18="");"";SI(J18<=H18;"SÍ";"NO")) | O18: =SI(O(I18="";K18="");"";SI(K18<=SI(M18<>"";M18;I18);"SÍ";"NO")) | P18: =SI(O(N18="";O18="");"";SI(Y(N18="SÍ";O18="SÍ");"SÍ";"NO")) | Q18: =SI(O(I18="";K18="");"";MAX(0;ENTERO(K18)-ENTERO(SI(M18<>"";M18;I18)))) | U18: 32
A19: 7303 | B19: ARAUCA | C19: Arauca | D19: Arauca | E19: BOGOTA | F19: JOAQUIN DE JESUS ROMERO PIÑEREZ | G19: 5 | H19: 46266 | I19: 46266 | J19: 46266 | K19: 46266 | L19: Finalizada | N19: =SI(O(H19="";J19="");"";SI(J19<=H19;"SÍ";"NO")) | O19: =SI(O(I19="";K19="");"";SI(K19<=SI(M19<>"";M19;I19);"SÍ";"NO")) | P19: =SI(O(N19="";O19="");"";SI(Y(N19="SÍ";O19="SÍ");"SÍ";"NO")) | Q19: =SI(O(I19="";K19="");"";MAX(0;ENTERO(K19)-ENTERO(SI(M19<>"";M19;I19)))) | R19: N/A - A Tiempo | S19: Pendiente Firma | U19: 34
A20: 7901 | B20: SIBUNDOY | C20: Sibundoy | D20: Putumayo | E20: SUR | F20: JOSE EVANGELISTA PINCHAO PINCHAO | G20: 3 | H20: 46266 | I20: 46267 | J20: 46266 | L20: En Proceso | N20: =SI(O(H20="";J20="");"";SI(J20<=H20;"SÍ";"NO")) | O20: =SI(O(I20="";K20="");"";SI(K20<=SI(M20<>"";M20;I20);"SÍ";"NO")) | P20: =SI(O(N20="";O20="");"";SI(Y(N20="SÍ";O20="SÍ");"SÍ";"NO")) | Q20: =SI(O(I20="";K20="");"";MAX(0;ENTERO(K20)-ENTERO(SI(M20<>"";M20;I20)))) | U20: 31
A21: 8510 | B21: LA PRIMAVERA | C21: La Primavera | D21: Vichada | E21: BOGOTA | F21: Andres Diaz | G21: 2 | H21: 46266 | I21: 46272 | J21: 46266 | L21: En Proceso | N21: =SI(O(H21="";J21="");"";SI(J21<=H21;"SÍ";"NO")) | O21: =SI(O(I21="";K21="");"";SI(K21<=SI(M21<>"";M21;I21);"SÍ";"NO")) | P21: =SI(O(N21="";O21="");"";SI(Y(N21="SÍ";O21="SÍ");"SÍ";"NO")) | Q21: =SI(O(I21="";K21="");"";MAX(0;ENTERO(K21)-ENTERO(SI(M21<>"";M21;I21)))) | U21: 17
A22: 9000 | B22: AVIANCA | C22: Bogotá, D.C. | D22: Cundinamarca | E22: DIRECCION GENERAL | F22: Grupo Bogota | G22: 936 | H22: 46266 | I22: 46367 | J22: 46266 | L22: En Proceso | N22: =SI(O(H22="";J22="");"";SI(J22<=H22;"SÍ";"NO")) | O22: =SI(O(I22="";K22="");"";SI(K22<=SI(M22<>"";M22;I22);"SÍ";"NO")) | P22: =SI(O(N22="";O22="");"";SI(Y(N22="SÍ";O22="SÍ");"SÍ";"NO")) | Q22: =SI(O(I22="";K22="");"";MAX(0;ENTERO(K22)-ENTERO(SI(M22<>"";M22;I22)))) | U22: 1713
A23: 9000 | B23: DIRECCION GENERAL | C23: Bogotá, D.C. | D23: Cundinamarca | E23: DIRECCION GENERAL | F23: Grupo Bogota | G23: 1022 | H23: 46266 | I23: 46367 | J23: 46266 | L23: En Proceso | N23: =SI(O(H23="";J23="");"";SI(J23<=H23;"SÍ";"NO")) | O23: =SI(O(I23="";K23="");"";SI(K23<=SI(M23<>"";M23;I23);"SÍ";"NO")) | P23: =SI(O(N23="";O23="");"";SI(Y(N23="SÍ";O23="SÍ");"SÍ";"NO")) | Q23: =SI(O(I23="";K23="");"";MAX(0;ENTERO(K23)-ENTERO(SI(M23<>"";M23;I23)))) | U23: 1637
A24: 9000 | B24: SUDAMERIS | C24: Bogotá, D.C. | D24: Cundinamarca | E24: DIRECCION GENERAL | F24: Grupo Bogota | G24: 43 | H24: 46266 | I24: 46367 | J24: 46266 | L24: En Proceso | N24: =SI(O(H24="";J24="");"";SI(J24<=H24;"SÍ";"NO")) | O24: =SI(O(I24="";K24="");"";SI(K24<=SI(M24<>"";M24;I24);"SÍ";"NO")) | P24: =SI(O(N24="";O24="");"";SI(Y(N24="SÍ";O24="SÍ");"SÍ";"NO")) | Q24: =SI(O(I24="";K24="");"";MAX(0;ENTERO(K24)-ENTERO(SI(M24<>"";M24;I24)))) | U24: 73
A25: 1381 | B25: RIONEGRO | C25: Rionegro | D25: Antioquia | E25: ANTIOQUIA | F25: Juan Pablo Osorio Ramirez | G25: 8 | H25: 46267 | I25: 46267 | L25: Programada | N25: =SI(O(H25="";J25="");"";SI(J25<=H25;"SÍ";"NO")) | O25: =SI(O(I25="";K25="");"";SI(K25<=SI(M25<>"";M25;I25);"SÍ";"NO")) | P25: =SI(O(N25="";O25="");"";SI(Y(N25="SÍ";O25="SÍ");"SÍ";"NO")) | Q25: =SI(O(I25="";K25="");"";MAX(0;ENTERO(K25)-ENTERO(SI(M25<>"";M25;I25)))) | U25: 35
A26: 1504 | B26: BELEN | C26: Belén | D26: Boyacá | E26: ORIENTE | F26: Andrés Felipe Carvajal Pire | G26: 4 | H26: 46267 | I26: 46268 | L26: Programada | N26: =SI(O(H26="";J26="");"";SI(J26<=H26;"SÍ";"NO")) | O26: =SI(O(I26="";K26="");"";SI(K26<=SI(M26<>"";M26;I26);"SÍ";"NO")) | P26: =SI(O(N26="";O26="");"";SI(Y(N26="SÍ";O26="SÍ");"SÍ";"NO")) | Q26: =SI(O(I26="";K26="");"";MAX(0;ENTERO(K26)-ENTERO(SI(M26<>"";M26;I26)))) | U26: 24
A27: 1522 | B27: COVARACHIA | C27: Covarachía | D27: Boyacá | E27: ORIENTE | F27: Mauricio Andrés Rivera Páez | G27: 1 | H27: 46267 | I27: 46268 | L27: Programada | N27: =SI(O(H27="";J27="");"";SI(J27<=H27;"SÍ";"NO")) | O27: =SI(O(I27="";K27="");"";SI(K27<=SI(M27<>"";M27;I27);"SÍ";"NO")) | P27: =SI(O(N27="";O27="");"";SI(Y(N27="SÍ";O27="SÍ");"SÍ";"NO")) | Q27: =SI(O(I27="";K27="");"";MAX(0;ENTERO(K27)-ENTERO(SI(M27<>"";M27;I27)))) | U27: 13
A28: 1524 | B28: EL COCUY | C28: El Cocuy | D28: Boyacá | E28: ORIENTE | F28: Luz Nélida Barragán Toro | G28: 3 | H28: 46267 | I28: 46268 | L28: Programada | N28: =SI(O(H28="";J28="");"";SI(J28<=H28;"SÍ";"NO")) | O28: =SI(O(I28="";K28="");"";SI(K28<=SI(M28<>"";M28;I28);"SÍ";"NO")) | P28: =SI(O(N28="";O28="");"";SI(Y(N28="SÍ";O28="SÍ");"SÍ";"NO")) | Q28: =SI(O(I28="";K28="");"";MAX(0;ENTERO(K28)-ENTERO(SI(M28<>"";M28;I28)))) | U28: 17
A29: 1576 | B29: SOATA | C29: Soatá | D29: Boyacá | E29: ORIENTE | F29: Mauricio Andrés Rivera Páez Y ANDRES FELIPE DIAZ | G29: 5 | H29: 46267 | I29: 46269 | L29: Programada | N29: =SI(O(H29="";J29="");"";SI(J29<=H29;"SÍ";"NO")) | O29: =SI(O(I29="";K29="");"";SI(K29<=SI(M29<>"";M29;I29);"SÍ";"NO")) | P29: =SI(O(N29="";O29="");"";SI(Y(N29="SÍ";O29="SÍ");"SÍ";"NO")) | Q29: =SI(O(I29="";K29="");"";MAX(0;ENTERO(K29)-ENTERO(SI(M29<>"";M29;I29)))) | U29: 31
A30: 2413 | B30: FONSECA | C30: Fonseca | D30: La Guajira | E30: COSTA | F30: Karen Katerine Beleño Andrade | G30: 2 | H30: 46267 | I30: 46267 | L30: Programada | N30: =SI(O(H30="";J30="");"";SI(J30<=H30;"SÍ";"NO")) | O30: =SI(O(I30="";K30="");"";SI(K30<=SI(M30<>"";M30;I30);"SÍ";"NO")) | P30: =SI(O(N30="";O30="");"";SI(Y(N30="SÍ";O30="SÍ");"SÍ";"NO")) | Q30: =SI(O(I30="";K30="");"";MAX(0;ENTERO(K30)-ENTERO(SI(M30<>"";M30;I30)))) | U30: 22
A31: 2745 | B31: LORICA | C31: Lorica | D31: Córdoba | E31: COSTA | F31: Dimar Jose Morelo Cardona | G31: 4 | H31: 46267 | I31: 46267 | L31: Programada | N31: =SI(O(H31="";J31="");"";SI(J31<=H31;"SÍ";"NO")) | O31: =SI(O(I31="";K31="");"";SI(K31<=SI(M31<>"";M31;I31);"SÍ";"NO")) | P31: =SI(O(N31="";O31="");"";SI(Y(N31="SÍ";O31="SÍ");"SÍ";"NO")) | Q31: =SI(O(I31="";K31="");"";MAX(0;ENTERO(K31)-ENTERO(SI(M31<>"";M31;I31)))) | U31: 27
A32: 2765 | B32: PLANETA RICA | C32: Planeta Rica | D32: Córdoba | E32: ANTIOQUIA | F32: Jorge Felipe Munive Medina | G32: 5 | H32: 46267 | I32: 46267 | L32: Programada | N32: =SI(O(H32="";J32="");"";SI(J32<=H32;"SÍ";"NO")) | O32: =SI(O(I32="";K32="");"";SI(K32<=SI(M32<>"";M32;I32);"SÍ";"NO")) | P32: =SI(O(N32="";O32="");"";SI(Y(N32="SÍ";O32="SÍ");"SÍ";"NO")) | Q32: =SI(O(I32="";K32="");"";MAX(0;ENTERO(K32)-ENTERO(SI(M32<>"";M32;I32)))) | U32: 32
A33: 3640 | B33: SAN JUAN DEL CESAR | C33: San Juan Del Cesar | D33: La Guajira | E33: COSTA | F33: Alberto Luis Pinto Acosta | G33: 4 | H33: 46267 | I33: 46267 | L33: Programada | N33: =SI(O(H33="";J33="");"";SI(J33<=H33;"SÍ";"NO")) | O33: =SI(O(I33="";K33="");"";SI(K33<=SI(M33<>"";M33;I33);"SÍ";"NO")) | P33: =SI(O(N33="";O33="");"";SI(Y(N33="SÍ";O33="SÍ");"SÍ";"NO")) | Q33: =SI(O(I33="";K33="");"";MAX(0;ENTERO(K33)-ENTERO(SI(M33<>"";M33;I33)))) | U33: 30
A34: 3910 | B34: COLOMBIA | C34: Colombia | D34: Huila | E34: SUR | F34: HAROLD STEED GARCIA | G34: 1 | H34: 46267 | I34: 46268 | L34: Programada | N34: =SI(O(H34="";J34="");"";SI(J34<=H34;"SÍ";"NO")) | O34: =SI(O(I34="";K34="");"";SI(K34<=SI(M34<>"";M34;I34);"SÍ";"NO")) | P34: =SI(O(N34="";O34="");"";SI(Y(N34="SÍ";O34="SÍ");"SÍ";"NO")) | Q34: =SI(O(I34="";K34="");"";MAX(0;ENTERO(K34)-ENTERO(SI(M34<>"";M34;I34)))) | U34: 16
A35: 4509 | B35: CASTILLA LA NUEVA | C35: Castilla La Nueva | D35: Meta | E35: BOGOTA | F35: Andres Felipe Balbin | G35: 2 | H35: 46267 | I35: 46267 | L35: Programada | N35: =SI(O(H35="";J35="");"";SI(J35<=H35;"SÍ";"NO")) | O35: =SI(O(I35="";K35="");"";SI(K35<=SI(M35<>"";M35;I35);"SÍ";"NO")) | P35: =SI(O(N35="";O35="");"";SI(Y(N35="SÍ";O35="SÍ");"SÍ";"NO")) | Q35: =SI(O(I35="";K35="");"";MAX(0;ENTERO(K35)-ENTERO(SI(M35<>"";M35;I35)))) | U35: 16
A36: 4884 | B36: CONSACA | C36: Consacá | D36: Nariño | E36: OCCIDENTE | F36: Juan Carlos Narvaez Acosta / Luis Fernando Ibarra Guio | G36: 2 | H36: 46267 | I36: 46267 | L36: Programada | N36: =SI(O(H36="";J36="");"";SI(J36<=H36;"SÍ";"NO")) | O36: =SI(O(I36="";K36="");"";SI(K36<=SI(M36<>"";M36;I36);"SÍ";"NO")) | P36: =SI(O(N36="";O36="");"";SI(Y(N36="SÍ";O36="SÍ");"SÍ";"NO")) | Q36: =SI(O(I36="";K36="");"";MAX(0;ENTERO(K36)-ENTERO(SI(M36<>"";M36;I36)))) | U36: 15
... A100: 8601 | B100: AGUAZUL | C100: Aguazul | D100: Casanare | E100: ORIENTE | F100: Juan Sebastian Lopez Acevedo | G100: 3 | H100: 46272 | I100: 46273 | L100: Programada | N100: =SI(O(H100="";J100="");"";SI(J100<=H100;"SÍ";"NO")) | O100: =SI(O(I100="";K100="");"";SI(K100<=SI(M100<>"";M100;I100);"SÍ";"NO")) | P100: =SI(O(N100="";O100="");"";SI(Y(N100="SÍ";O100="SÍ");"SÍ";"NO")) | Q100: =SI(O(I100="";K100="");"";MAX(0;ENTERO(K100)-ENTERO(SI(M100<>"";M100;I100)))) | U100: 23
A101: 1300 | B101: GERENCIA REGIONAL ANTIOQUIA | C101: Bogota | E101: ANTIOQUIA | F101: JONATHAN FELIPE JARABE CHALARCA | G101: 119 | H101: 46272 | I101: 46367 | L101: Programada | N101: =SI(O(H101="";J101="");"";SI(J101<=H101;"SÍ";"NO")) | O101: =SI(O(I101="";K101="");"";SI(K101<=SI(M101<>"";M101;I101);"SÍ";"NO")) | P101: =SI(O(N101="";O101="");"";SI(Y(N101="SÍ";O101="SÍ");"SÍ";"NO")) | Q101: =SI(O(I101="";K101="");"";MAX(0;ENTERO(K101)-ENTERO(SI(M101<>"";M101;I101)))) | U101: 181
A102: 1500 | B102: GERENCIA REGIONAL BOGOTA | E102: BOGOTA | F102: Grupo Bogota | G102: 81 | H102: 46272 | I102: 46367 | L102: Programada | N102: =SI(O(H102="";J102="");"";SI(J102<=H102;"SÍ";"NO")) | O102: =SI(O(I102="";K102="");"";SI(K102<=SI(M102<>"";M102;I102);"SÍ";"NO")) | P102: =SI(O(N102="";O102="");"";SI(Y(N102="SÍ";O102="SÍ");"SÍ";"NO")) | Q102: =SI(O(I102="";K102="");"";MAX(0;ENTERO(K102)-ENTERO(SI(M102<>"";M102;I102)))) | U102: 146
A103: 1600 | B103: REGIONAL REGIONAL CAFETERA | E103: CAFETERA | F103: DIEGO ALEJANDRO HERNÁNDEZ OROZCO | G103: 92 | H103: 46272 | I103: 46367 | L103: Programada | N103: =SI(O(H103="";J103="");"";SI(J103<=H103;"SÍ";"NO")) | O103: =SI(O(I103="";K103="");"";SI(K103<=SI(M103<>"";M103;I103);"SÍ";"NO")) | P103: =SI(O(N103="";O103="");"";SI(Y(N103="SÍ";O103="SÍ");"SÍ";"NO")) | Q103: =SI(O(I103="";K103="");"";MAX(0;ENTERO(K103)-ENTERO(SI(M103<>"";M103;I103)))) | U103: 138
...

Sheet Dashboard_KPIs
A1: TABLERO DE CONTROL · MANTENIMIENTOS PREVENTIVOS | M1: PARÁMETROS
A2: Avance diario de mantenimientos preventivos y auditoría de calidad — Fuente: Bitacora_Diaria | K2: Actualizado: | L2: =HOY() | M2: Mes (número) | N2: 9
M3: Año | N3: 2026
A4: INDICADORES GENERALES | M4: Meta % Cumplimiento | N4: 0.95
A5: TOTAL MANTENIMIENTOS | D5: EJECUTADAS | G5: PENDIENTES | J5: AVANCE DEL PLAN | M5: Meta % Desviación | N5: 0.05
A6: =CONTARA(Bitacora_Diaria!A2:A100000) | D6: =CONTAR.SI(Bitacora_Diaria!L2:L100000;"Finalizada")+CONTAR.SI(Bitacora_Diaria!L2:L100000;"Sede_Cerrada") | G6: =CONTAR.SI(Bitacora_Diaria!L2:L100000;"Programada")+CONTAR.SI(Bitacora_Diaria!L2:L100000;"En Proceso")+CONTAR.SI(Bitacora_Diaria!L2:L100000;"Reprogramada") | J6: =SI(A6=0;0;D6/A6) | M6: Fecha de corte | N6: =HOY()
A8: Registros de la bitácora | F8: Finalizada + Sede_Cerrada | I8: Programada + En Proceso + Reprogramada | L8: Ejecutadas / Total
A10: CUMPLIMIENTO Y DESVIACIÓN
A11: TASA DE CUMPLIMIENTO | D11: DESVIACIÓN DEL CRONOGRAMA | G11: DESVIACIÓN PROMEDIO | J11: POR COMPLETAR | M11: CÁLCULOS (no editar)
A12: =SI(N12=0;0;N13/N12) | D12: =SI(N12=0;0;N14/N12) | G12: =SI.ERROR(PROMEDIO.SI.CONJUNTO(Bitacora_Diaria!Q2:Q100000;Bitacora_Diaria!P2:P100000;"NO");0) | J12: =D6-N15 | M12: Evaluables (SÍ + NO + Reprogramadas) | N12: =CONTAR.SI(Bitacora_Diaria!P2:P100000;"SÍ")+CONTAR.SI(Bitacora_Diaria!P2:P100000;"NO")+CONTAR.SI(Bitacora_Diaria!L2:L100000;"Reprogramada")
M13: Cumplen (SÍ) | N13: =CONTAR.SI(Bitacora_Diaria!P2:P100000;"SÍ")
A14: SÍ / Evaluables | F14: (NO + Reprogramadas) / Evaluables | I14: Días promedio de retraso | L14: Ejecutadas sin fecha de cierre | M14: Desvían (NO + Reprogramadas) | N14: =CONTAR.SI(Bitacora_Diaria!P2:P100000;"NO")+CONTAR.SI(Bitacora_Diaria!L2:L100000;"Reprogramada")
M15: Ejecutadas con fecha de cierre | N15: =CONTAR.SI.CONJUNTO(Bitacora_Diaria!L2:L100000;"Finalizada";Bitacora_Diaria!K2:K100000;"<>")+CONTAR.SI.CONJUNTO(Bitacora_Diaria!L2:L100000;"Sede_Cerrada";Bitacora_Diaria!K2:K100000;"<>")
A16: IMPACTO DIARIO (MES EN PARÁMETROS) | M16: Acumulado del mes | N16: =CONTAR.SI.CONJUNTO(Bitacora_Diaria!K2:K100000;">="&FECHA(N3;N2;1);Bitacora_Diaria!K2:K100000;"<="&FECHA(N3;N2+1;0))
A17: EJECUTADAS HOY | D17: PROMEDIO DIARIO | G17: MÁXIMO EN EL DÍA | J17: ACUMULADO DEL MES | M17: Días transcurridos del mes | N17: =MAX(1;MIN(HOY();FECHA(N3;N2+1;0))-FECHA(N3;N2;1)+1)
A18: =CONTAR.SI.CONJUNTO(Bitacora_Diaria!K2:K100000;">="&HOY();Bitacora_Diaria!K2:K100000;"<"&HOY()+1) | D18: =N19 | G18: =N18 | J18: =N16 | M18: Máximo en el día | N18: =MAX(N23:N54)
M19: Promedio diario | N19: =SI(N16=0;0;N16/N17)
A20: Cierres operativos de hoy | F20: Acumulado / días transcurridos | I20: Mayor cantidad en un día | L20: Cierres del mes seleccionado
A22: AVANCE DIARIO — PLAN VS EJECUTADO | M22: Fecha | N22: Ejecutadas | O22: Programadas | P22: Acumulado
M23: =FECHA(N3;N2;1) | N23: =SI(M23="";"";CONTAR.SI.CONJUNTO(Bitacora_Diaria!K2:K100000;">="&M23;Bitacora_Diaria!K2:K100000;"<"&M23+1)) | O23: =SI(M23="";"";CONTAR.SI.CONJUNTO(Bitacora_Diaria!H2:H100000;">="&M23;Bitacora_Diaria!H2:H100000;"<"&M23+1)) | P23: =SI(M23="";"";CONTAR.SI.CONJUNTO(Bitacora_Diaria!K2:K100000;">="&FECHA(N3;N2;1);Bitacora_Diaria!K2:K100000;"<="&M23))
M24: =SI(M23="";"";SI(M23>=FECHA(N3;N2+1;0);"";M23+1)) | N24: =SI(M24="";"";CONTAR.SI.CONJUNTO(Bitacora_Diaria!K2:K100000;">="&M24;Bitacora_Diaria!K2:K100000;"<"&M24+1)) | O24: =SI(M24="";"";CONTAR.SI.CONJUNTO(Bitacora_Diaria!H2:H100000;">="&M24;Bitacora_Diaria!H2:H100000;"<"&M24+1)) | P24: =SI(M24="";"";CONTAR.SI.CONJUNTO(Bitacora_Diaria!K2:K100000;">="&FECHA(N3;N2;1);Bitacora_Diaria!K2:K100000;"<="&M24))
M25: =SI(M24="";"";SI(M24>=FECHA(N3;N2+1;0);"";M24+1)) | N25: =SI(M25="";"";CONTAR.SI.CONJUNTO(Bitacora_Diaria!K2:K100000;">="&M25;Bitacora_Diaria!K2:K100000;"<"&M25+1)) | O25: =SI(M25="";"";CONTAR.SI.CONJUNTO(Bitacora_Diaria!H2:H100000;">="&M25;Bitacora_Diaria!H2:H100000;"<"&M25+1)) | P25: =SI(M25="";"";CONTAR.SI.CONJUNTO(Bitacora_Diaria!K2:K100000;">="&FECHA(N3;N2;1);Bitacora_Diaria!K2:K100000;"<="&M25))
M26: =SI(M25="";"";SI(M25>=FECHA(N3;N2+1;0);"";M25+1)) | N26: =SI(M26="";"";CONTAR.SI.CONJUNTO(Bitacora_Diaria!K2:K100000;">="&M26;Bitacora_Diaria!K2:K100000;"<"&M26+1)) | O26: =SI(M26="";"";CONTAR.SI.CONJUNTO(Bitacora_Diaria!H2:H100000;">="&M26;Bitacora_Diaria!H2:H100000;"<"&M26+1)) | P26: =SI(M26="";"";CONTAR.SI.CONJUNTO(Bitacora_Diaria!K2:K100000;">="&FECHA(N3;N2;1);Bitacora_Diaria!K2:K100000;"<="&M26))
M27: =SI(M26="";"";SI(M26>=FECHA(N3;N2+1;0);"";M26+1)) | N27: =SI(M27="";"";CONTAR.SI.CONJUNTO(Bitacora_Diaria!K2:K100000;">="&M27;Bitacora_Diaria!K2:K100000;"<"&M27+1)) | O27: =SI(M27="";"";CONTAR.SI.CONJUNTO(Bitacora_Diaria!H2:H100000;">="&M27;Bitacora_Diaria!H2:H100000;"<"&M27+1)) | P27: =SI(M27="";"";CONTAR.SI.CONJUNTO(Bitacora_Diaria!K2:K100000;">="&FECHA(N3;N2;1);Bitacora_Diaria!K2:K100000;"<="&M27))
M28: =SI(M27="";"";SI(M27>=FECHA(N3;N2+1;0);"";M27+1)) | N28: =SI(M28="";"";CONTAR.SI.CONJUNTO(Bitacora_Diaria!K2:K100000;">="&M28;Bitacora_Diaria!K2:K100000;"<"&M28+1)) | O28: =SI(M28="";"";CONTAR.SI.CONJUNTO(Bitacora_Diaria!H2:H100000;">="&M28;Bitacora_Diaria!H2:H100000;"<"&M28+1)) | P28: =SI(M28="";"";CONTAR.SI.CONJUNTO(Bitacora_Diaria!K2:K100000;">="&FECHA(N3;N2;1);Bitacora_Diaria!K2:K100000;"<="&M28))
M29: =SI(M28="";"";SI(M28>=FECHA(N3;N2+1;0);"";M28+1)) | N29: =SI(M29="";"";CONTAR.SI.CONJUNTO(Bitacora_Diaria!K2:K100000;">="&M29;Bitacora_Diaria!K2:K100000;"<"&M29+1)) | O29: =SI(M29="";"";CONTAR.SI.CONJUNTO(Bitacora_Diaria!H2:H100000;">="&M29;Bitacora_Diaria!H2:H100000;"<"&M29+1)) | P29: =SI(M29="";"";CONTAR.SI.CONJUNTO(Bitacora_Diaria!K2:K100000;">="&FECHA(N3;N2;1);Bitacora_Diaria!K2:K100000;"<="&M29))
M30: =SI(M29="";"";SI(M29>=FECHA(N3;N2+1;0);"";M29+1)) | N30: =SI(M30="";"";CONTAR.SI.CONJUNTO(Bitacora_Diaria!K2:K100000;">="&M30;Bitacora_Diaria!K2:K100000;"<"&M30+1)) | O30: =SI(M30="";"";CONTAR.SI.CONJUNTO(Bitacora_Diaria!H2:H100000;">="&M30;Bitacora_Diaria!H2:H100000;"<"&M30+1)) | P30: =SI(M30="";"";CONTAR.SI.CONJUNTO(Bitacora_Diaria!K2:K100000;">="&FECHA(N3;N2;1);Bitacora_Diaria!K2:K100000;"<="&M30))
M31: =SI(M30="";"";SI(M30>=FECHA(N3;N2+1;0);"";M30+1)) | N31: =SI(M31="";"";CONTAR.SI.CONJUNTO(Bitacora_Diaria!K2:K100000;">="&M31;Bitacora_Diaria!K2:K100000;"<"&M31+1)) | O31: =SI(M31="";"";CONTAR.SI.CONJUNTO(Bitacora_Diaria!H2:H100000;">="&M31;Bitacora_Diaria!H2:H100000;"<"&M31+1)) | P31: =SI(M31="";"";CONTAR.SI.CONJUNTO(Bitacora_Diaria!K2:K100000;">="&FECHA(N3;N2;1);Bitacora_Diaria!K2:K100000;"<="&M31))
M32: =SI(M31="";"";SI(M31>=FECHA(N3;N2+1;0);"";M31+1)) | N32: =SI(M32="";"";CONTAR.SI.CONJUNTO(Bitacora_Diaria!K2:K100000;">="&M32;Bitacora_Diaria!K2:K100000;"<"&M32+1)) | O32: =SI(M32="";"";CONTAR.SI.CONJUNTO(Bitacora_Diaria!H2:H100000;">="&M32;Bitacora_Diaria!H2:H100000;"<"&M32+1)) | P32: =SI(M32="";"";CONTAR.SI.CONJUNTO(Bitacora_Diaria!K2:K100000;">="&FECHA(N3;N2;1);Bitacora_Diaria!K2:K100000;"<="&M32))
M33: =SI(M32="";"";SI(M32>=FECHA(N3;N2+1;0);"";M32+1)) | N33: =SI(M33="";"";CONTAR.SI.CONJUNTO(Bitacora_Diaria!K2:K100000;">="&M33;Bitacora_Diaria!K2:K100000;"<"&M33+1)) | O33: =SI(M33="";"";CONTAR.SI.CONJUNTO(Bitacora_Diaria!H2:H100000;">="&M33;Bitacora_Diaria!H2:H100000;"<"&M33+1)) | P33: =SI(M33="";"";CONTAR.SI.CONJUNTO(Bitacora_Diaria!K2:K100000;">="&FECHA(N3;N2;1);Bitacora_Diaria!K2:K100000;"<="&M33))
M34: =SI(M33="";"";SI(M33>=FECHA(N3;N2+1;0);"";M33+1)) | N34: =SI(M34="";"";CONTAR.SI.CONJUNTO(Bitacora_Diaria!K2:K100000;">="&M34;Bitacora_Diaria!K2:K100000;"<"&M34+1)) | O34: =SI(M34="";"";CONTAR.SI.CONJUNTO(Bitacora_Diaria!H2:H100000;">="&M34;Bitacora_Diaria!H2:H100000;"<"&M34+1)) | P34: =SI(M34="";"";CONTAR.SI.CONJUNTO(Bitacora_Diaria!K2:K100000;">="&FECHA(N3;N2;1);Bitacora_Diaria!K2:K100000;"<="&M34))
M35: =SI(M34="";"";SI(M34>=FECHA(N3;N2+1;0);"";M34+1)) | N35: =SI(M35="";"";CONTAR.SI.CONJUNTO(Bitacora_Diaria!K2:K100000;">="&M35;Bitacora_Diaria!K2:K100000;"<"&M35+1)) | O35: =SI(M35="";"";CONTAR.SI.CONJUNTO(Bitacora_Diaria!H2:H100000;">="&M35;Bitacora_Diaria!H2:H100000;"<"&M35+1)) | P35: =SI(M35="";"";CONTAR.SI.CONJUNTO(Bitacora_Diaria!K2:K100000;">="&FECHA(N3;N2;1);Bitacora_Diaria!K2:K100000;"<="&M35))
M36: =SI(M35="";"";SI(M35>=FECHA(N3;N2+1;0);"";M35+1)) | N36: =SI(M36="";"";CONTAR.SI.CONJUNTO(Bitacora_Diaria!K2:K100000;">="&M36;Bitacora_Diaria!K2:K100000;"<"&M36+1)) | O36: =SI(M36="";"";CONTAR.SI.CONJUNTO(Bitacora_Diaria!H2:H100000;">="&M36;Bitacora_Diaria!H2:H100000;"<"&M36+1)) | P36: =SI(M36="";"";CONTAR.SI.CONJUNTO(Bitacora_Diaria!K2:K100000;">="&FECHA(N3;N2;1);Bitacora_Diaria!K2:K100000;"<="&M36))
M37: =SI(M36="";"";SI(M36>=FECHA(N3;N2+1;0);"";M36+1)) | N37: =SI(M37="";"";CONTAR.SI.CONJUNTO(Bitacora_Diaria!K2:K100000;">="&M37;Bitacora_Diaria!K2:K100000;"<"&M37+1)) | O37: =SI(M37="";"";CONTAR.SI.CONJUNTO(Bitacora_Diaria!H2:H100000;">="&M37;Bitacora_Diaria!H2:H100000;"<"&M37+1)) | P37: =SI(M37="";"";CONTAR.SI.CONJUNTO(Bitacora_Diaria!K2:K100000;">="&FECHA(N3;N2;1);Bitacora_Diaria!K2:K100000;"<="&M37))
M38: =SI(M37="";"";SI(M37>=FECHA(N3;N2+1;0);"";M37+1)) | N38: =SI(M38="";"";CONTAR.SI.CONJUNTO(Bitacora_Diaria!K2:K100000;">="&M38;Bitacora_Diaria!K2:K100000;"<"&M38+1)) | O38: =SI(M38="";"";CONTAR.SI.CONJUNTO(Bitacora_Diaria!H2:H100000;">="&M38;Bitacora_Diaria!H2:H100000;"<"&M38+1)) | P38: =SI(M38="";"";CONTAR.SI.CONJUNTO(Bitacora_Diaria!K2:K100000;">="&FECHA(N3;N2;1);Bitacora_Diaria!K2:K100000;"<="&M38))
M39: =SI(M38="";"";SI(M38>=FECHA(N3;N2+1;0);"";M38+1)) | N39: =SI(M39="";"";CONTAR.SI.CONJUNTO(Bitacora_Diaria!K2:K100000;">="&M39;Bitacora_Diaria!K2:K100000;"<"&M39+1)) | O39: =SI(M39="";"";CONTAR.SI.CONJUNTO(Bitacora_Diaria!H2:H100000;">="&M39;Bitacora_Diaria!H2:H100000;"<"&M39+1)) | P39: =SI(M39="";"";CONTAR.SI.CONJUNTO(Bitacora_Diaria!K2:K100000;">="&FECHA(N3;N2;1);Bitacora_Diaria!K2:K100000;"<="&M39))
M40: =SI(M39="";"";SI(M39>=FECHA(N3;N2+1;0);"";M39+1)) | N40: =SI(M40="";"";CONTAR.SI.CONJUNTO(Bitacora_Diaria!K2:K100000;">="&M40;Bitacora_Diaria!K2:K100000;"<"&M40+1)) | O40: =SI(M40="";"";CONTAR.SI.CONJUNTO(Bitacora_Diaria!H2:H100000;">="&M40;Bitacora_Diaria!H2:H100000;"<"&M40+1)) | P40: =SI(M40="";"";CONTAR.SI.CONJUNTO(Bitacora_Diaria!K2:K100000;">="&FECHA(N3;N2;1);Bitacora_Diaria!K2:K100000;"<="&M40))
A41: MANTENIMIENTOS POR REGIÓN | M41: =SI(M40="";"";SI(M40>=FECHA(N3;N2+1;0);"";M40+1)) | N41: =SI(M41="";"";CONTAR.SI.CONJUNTO(Bitacora_Diaria!K2:K100000;">="&M41;Bitacora_Diaria!K2:K100000;"<"&M41+1)) | O41: =SI(M41="";"";CONTAR.SI.CONJUNTO(Bitacora_Diaria!H2:H100000;">="&M41;Bitacora_Diaria!H2:H100000;"<"&M41+1)) | P41: =SI(M41="";"";CONTAR.SI.CONJUNTO(Bitacora_Diaria!K2:K100000;">="&FECHA(N3;N2;1);Bitacora_Diaria!K2:K100000;"<="&M41))
A42: Región | B42: Total | C42: Ejecutadas | D42: % Cumplimiento | E42: % Desviación | F42: Desv. prom. (días) | G42: Evaluables | H42: Cumplen | I42: Desvían | M42: =SI(M41="";"";SI(M41>=FECHA(N3;N2+1;0);"";M41+1)) | N42: =SI(M42="";"";CONTAR.SI.CONJUNTO(Bitacora_Diaria!K2:K100000;">="&M42;Bitacora_Diaria!K2:K100000;"<"&M42+1)) | O42: =SI(M42="";"";CONTAR.SI.CONJUNTO(Bitacora_Diaria!H2:H100000;">="&M42;Bitacora_Diaria!H2:H100000;"<"&M42+1)) | P42: =SI(M42="";"";CONTAR.SI.CONJUNTO(Bitacora_Diaria!K2:K100000;">="&FECHA(N3;N2;1);Bitacora_Diaria!K2:K100000;"<="&M42))
A43: ANTIOQUIA | B43: =CONTAR.SI.CONJUNTO(Bitacora_Diaria!E2:E100000;A43) | C43: =CONTAR.SI.CONJUNTO(Bitacora_Diaria!E2:E100000;A43;Bitacora_Diaria!L2:L100000;"Finalizada")+CONTAR.SI.CONJUNTO(Bitacora_Diaria!E2:E100000;A43;Bitacora_Diaria!L2:L100000;"Sede_Cerrada") | D43: =SI(G43=0;0;H43/G43) | E43: =SI(G43=0;0;I43/G43) | F43: =SI.ERROR(PROMEDIO.SI.CONJUNTO(Bitacora_Diaria!Q2:Q100000;Bitacora_Diaria!E2:E100000;A43;Bitacora_Diaria!P2:P100000;"NO");0) | G43: =CONTAR.SI.CONJUNTO(Bitacora_Diaria!E2:E100000;A43;Bitacora_Diaria!P2:P100000;"SÍ")+CONTAR.SI.CONJUNTO(Bitacora_Diaria!E2:E100000;A43;Bitacora_Diaria!P2:P100000;"NO")+CONTAR.SI.CONJUNTO(Bitacora_Diaria!E2:E100000;A43;Bitacora_Diaria!L2:L100000;"Reprogramada") | H43: =CONTAR.SI.CONJUNTO(Bitacora_Diaria!E2:E100000;A43;Bitacora_Diaria!P2:P100000;"SÍ") | I43: =CONTAR.SI.CONJUNTO(Bitacora_Diaria!E2:E100000;A43;Bitacora_Diaria!P2:P100000;"NO")+CONTAR.SI.CONJUNTO(Bitacora_Diaria!E2:E100000;A43;Bitacora_Diaria!L2:L100000;"Reprogramada") | M43: =SI(M42="";"";SI(M42>=FECHA(N3;N2+1;0);"";M42+1)) | N43: =SI(M43="";"";CONTAR.SI.CONJUNTO(Bitacora_Diaria!K2:K100000;">="&M43;Bitacora_Diaria!K2:K100000;"<"&M43+1)) | O43: =SI(M43="";"";CONTAR.SI.CONJUNTO(Bitacora_Diaria!H2:H100000;">="&M43;Bitacora_Diaria!H2:H100000;"<"&M43+1)) | P43: =SI(M43="";"";CONTAR.SI.CONJUNTO(Bitacora_Diaria!K2:K100000;">="&FECHA(N3;N2;1);Bitacora_Diaria!K2:K100000;"<="&M43))
...
